Workbook

Sheet MPM
B2: Data of Meyer-Peter, E. and Muller, R. (1948), as per Smart and Jaeggi (1983) | AD2: nk | AE2: 2
B4: ID | C4: Q | D4: B | E4: H | F4: S | G4: Dm | H4: D90 | I4: sg | J4: R+1 | K4: Gb | L4: r | M4: n | N4: Q | O4: Dm | P4: D90 | Q4: U | R4: tb | S4: r | T4: Cf | U4: Re | V4: Cf/Re | W4: f/Re | X4: fw | Y4: Rew | Z4: Aw | AA4: Ab | AB4: rb | AC4: Cfb | AD4: tb | AE4: ks | AF4: Czb | AG4: Czbs | AH4: rbs | AI4: check | AJ4: Cfbs | AK4: tbs | AL4: tbs/tb
B5: N° | C5: L/s | D5: m | E5: m | G5: mm | H5: mm | K5: g/s | L5: kg/m3 | M5: m2/s | N5: m3/s | O5: m | P5: m | Q5: m/s | R5: Pa | S5: m | T5: - | U5: - | V5: - | W5: - | X5: - | Y5: - | Z5: m2 | AA5: m2 | AB5: m | AC5: - | AD5: Pa | AE5: m | AF5: - | AG5: - | AH5: - | AJ5: - | AK5: Pa | AL5: -
B6: 1 | C6: 1641 | D6: 2 | E6: 0.387 | F6: 0.0107 | G6: 28.65 | H6: 28.65 | I6: 1 | J6: 2.68 | K6: 1815.1 | L6: 1000 | M6: 1e-06 | N6: =C6/1000 -> 1.641 | O6: =G6/1000 -> 0.02865 | P6: =H6/1000 -> 0.02865 | Q6: =N6/(E6*D6) -> 2.120155 | R6: =L6*9.81*E6*F6 -> 40.622229 | S6: =D6*E6/(D6+2*E6) -> 0.27901947 | T6: =9.81*S6*F6/(Q6^2) -> 0.0065155645 | U6: =Q6*S6/M6 -> 591564.53 | V6: =T6/U6 -> 1.1014123e-08 | W6: =8*V6 -> 8.8112984e-08 | X6: =0.301*(W6^(1/5)) -> 0.011683541 | Y6: =X6/W6 -> 132597.27 | Z6: =2*M6*E6*Y6/Q6 -> 0.048406971 | AA6: =D6*E6-Z6 -> 0.72559303 | AB6: =AA6/D6 -> 0.36279651 | AC6: =(T6*(D6+2*E6)-X6*2*E6/8)/D6 -> 0.0084718967 | AD6: =1000*AC6*(Q6^2) -> 38.081662 | AE6: =AE$2*P6 -> 0.0573 | AF6: =1/(AC6^0.5) -> 10.864498 | AG6: =IF(AC6<(1/(Sheet1!BL5^2)),MPM!AF6,Sheet1!BL5) -> 10.978797 | AH6: =IF(AG6=AF6,AB6,Sheet1!BK5) -> 0.35528181 | AI6: =IF(AH6>AB6,"error","ok") -> ok | AJ6: =1/(AG6^2) -> 0.0082964159 | AK6: =L6*AJ6*(Q6^2) -> 37.292865 | AL6: =100*AK6/AD6 -> 97.928671
B7: =+B6+1 -> 2 | C7: 1641 | D7: 2 | E7: 0.444 | F7: 0.00654 | G7: 28.65 | H7: 28.65 | I7: 1 | J7: 2.68 | K7: 45.9 | L7: 1000 | M7: 1e-06 | N7: =C7/1000 -> 1.641 | O7: =G7/1000 -> 0.02865 | P7: =H7/1000 -> 0.02865 | Q7: =N7/(E7*D7) -> 1.847973 | R7: =L7*9.81*E7*F7 -> 28.485886 | S7: =D7*E7/(D7+2*E7) -> 0.30747922 | T7: =9.81*S7*F7/(Q7^2) -> 0.0057765868 | U7: =Q7*S7/M7 -> 568213.3 | V7: =T7/U7 -> 1.016623e-08 | W7: =8*V7 -> 8.1329836e-08 | X7: =0.301*(W7^(1/5)) -> 0.011497846 | Y7: =X7/W7 -> 141373.03 | Z7: =2*M7*E7*Y7/Q7 -> 0.06793349 | AA7: =D7*E7-Z7 -> 0.82006651 | AB7: =AA7/D7 -> 0.41003325 | AC7: =(T7*(D7+2*E7)-X7*2*E7/8)/D7 -> 0.0077032609 | AD7: =1000*AC7*(Q7^2) -> 26.306668 | AE7: =AE$2*P7 -> 0.0573 | AF7: =1/(AC7^0.5) -> 11.393645 | AG7: =IF(AC7<(1/(Sheet1!BL6^2)),MPM!AF7,Sheet1!BL6) -> 11.393645 | AH7: =IF(AG7=AF7,AB7,Sheet1!BK6) -> 0.41003325 | AI7: =IF(AH7>AB7,"error","ok") -> ok | AJ7: =1/(AG7^2) -> 0.0077032609 | AK7: =L7*AJ7*(Q7^2) -> 26.306668 | AL7: =100*AK7/AD7 -> 100
B8: =+B7+1 -> 3 | C8: 1641 | D8: 2 | E8: 0.397 | F8: 0.0092 | G8: 28.65 | H8: 28.65 | I8: 1 | J8: 2.68 | K8: 990.5 | L8: 1000 | M8: 1e-06 | N8: =C8/1000 -> 1.641 | O8: =G8/1000 -> 0.02865 | P8: =H8/1000 -> 0.02865 | Q8: =N8/(E8*D8) -> 2.0667506 | R8: =L8*9.81*E8*F8 -> 35.830044 | S8: =D8*E8/(D8+2*E8) -> 0.28418039 | T8: =9.81*S8*F8/(Q8^2) -> 0.0060044714 | U8: =Q8*S8/M8 -> 587329.99 | V8: =T8/U8 -> 1.0223335e-08 | W8: =8*V8 -> 8.1786681e-08 | X8: =0.301*(W8^(1/5)) -> 0.011510734 | Y8: =X8/W8 -> 140740.93 | Z8: =2*M8*E8*Y8/Q8 -> 0.054069562 | AA8: =D8*E8-Z8 -> 0.73993044 | AB8: =AA8/D8 -> 0.36996522 | AC8: =(T8*(D8+2*E8)-X8*2*E8/8)/D8 -> 0.0078170263 | AD8: =1000*AC8*(Q8^2) -> 33.390101 | AE8: =AE$2*P8 -> 0.0573 | AF8: =1/(AC8^0.5) -> 11.310433 | AG8: =IF(AC8<(1/(Sheet1!BL7^2)),MPM!AF8,Sheet1!BL7) -> 11.310433 | AH8: =IF(AG8=AF8,AB8,Sheet1!BK7) -> 0.36996522 | AI8: =IF(AH8>AB8,"error","ok") -> ok | AJ8: =1/(AG8^2) -> 0.0078170263 | AK8: =L8*AJ8*(Q8^2) -> 33.390101 | AL8: =100*AK8/AD8 -> 100
B9: =+B8+1 -> 4 | C9: 1641 | D9: 2 | E9: 0.399 | F9: 0.00928 | G9: 28.65 | H9: 28.65 | I9: 1 | J9: 2.68 | K9: 982.5 | L9: 1000 | M9: 1e-06 | N9: =C9/1000 -> 1.641 | O9: =G9/1000 -> 0.02865 | P9: =H9/1000 -> 0.02865 | Q9: =N9/(E9*D9) -> 2.056391 | R9: =L9*9.81*E9*F9 -> 36.323683 | S9: =D9*E9/(D9+2*E9) -> 0.28520372 | T9: =9.81*S9*F9/(Q9^2) -> 0.0061398928 | U9: =Q9*S9/M9 -> 586490.35 | V9: =T9/U9 -> 1.0468873e-08 | W9: =8*V9 -> 8.3750981e-08 | X9: =0.301*(W9^(1/5)) -> 0.011565502 | Y9: =X9/W9 -> 138093.93 | Z9: =2*M9*E9*Y9/Q9 -> 0.053588522 | AA9: =D9*E9-Z9 -> 0.74441148 | AB9: =AA9/D9 -> 0.37220574 | AC9: =(T9*(D9+2*E9)-X9*2*E9/8)/D9 -> 0.0080128806 | AD9: =1000*AC9*(Q9^2) -> 33.884419 | AE9: =AE$2*P9 -> 0.0573 | AF9: =1/(AC9^0.5) -> 11.17135 | AG9: =IF(AC9<(1/(Sheet1!BL8^2)),MPM!AF9,Sheet1!BL8) -> 11.17135 | AH9: =IF(AG9=AF9,AB9,Sheet1!BK8) -> 0.37220574 | AI9: =IF(AH9>AB9,"error","ok") -> ok | AJ9: =1/(AG9^2) -> 0.0080128806 | AK9: =L9*AJ9*(Q9^2) -> 33.884419 | AL9: =100*AK9/AD9 -> 100
B10: =+B9+1 -> 5 | C10: 1641 | D10: 2 | E10: 0.399 | F10: 0.00923 | G10: 28.65 | H10: 28.65 | I10: 1 | J10: 2.68 | K10: 979.3 | L10: 1000 | M10: 1e-06 | N10: =C10/1000 -> 1.641 | O10: =G10/1000 -> 0.02865 | P10: =H10/1000 -> 0.02865 | Q10: =N10/(E10*D10) -> 2.056391 | R10: =L10*9.81*E10*F10 -> 36.127974 | S10: =D10*E10/(D10+2*E10) -> 0.28520372 | T10: =9.81*S10*F10/(Q10^2) -> 0.0061068114 | U10: =Q10*S10/M10 -> 586490.35 | V10: =T10/U10 -> 1.0412467e-08 | W10: =8*V10 -> 8.3299736e-08 | X10: =0.301*(W10^(1/5)) -> 0.011553012 | Y10: =X10/W10 -> 138692.06 | Z10: =2*M10*E10*Y10/Q10 -> 0.053820632 | AA10: =D10*E10-Z10 -> 0.74417937 | AB10: =AA10/D10 -> 0.37208968 | AC10: =(T10*(D10+2*E10)-X10*2*E10/8)/D10 -> 0.0079672227 | AD10: =1000*AC10*(Q10^2) -> 33.691344 | AE10: =AE$2*P10 -> 0.0573 | AF10: =1/(AC10^0.5) -> 11.203314 | AG10: =IF(AC10<(1/(Sheet1!BL9^2)),MPM!AF10,Sheet1!BL9) -> 11.203314 | AH10: =IF(AG10=AF10,AB10,Sheet1!BK9) -> 0.37208968 | AI10: =IF(AH10>AB10,"error","ok") -> ok | AJ10: =1/(AG10^2) -> 0.0079672227 | AK10: =L10*AJ10*(Q10^2) -> 33.691344 | AL10: =100*AK10/AD10 -> 100
B11: =+B10+1 -> 6 | C11: 1641 | D11: 2 | E11: 0.399 | F11: 0.00915 | G11: 28.65 | H11: 28.65 | I11: 1 | J11: 2.68 | K11: 1012.8 | L11: 1000 | M11: 1e-06 | N11: =C11/1000 -> 1.641 | O11: =G11/1000 -> 0.02865 | P11: =H11/1000 -> 0.02865 | Q11: =N11/(E11*D11) -> 2.056391 | R11: =L11*9.81*E11*F11 -> 35.814839 | S11: =D11*E11/(D11+2*E11) -> 0.28520372 | T11: =9.81*S11*F11/(Q11^2) -> 0.0060538813 | U11: =Q11*S11/M11 -> 586490.35 | V11: =T11/U11 -> 1.0322218e-08 | W11: =8*V11 -> 8.2577745e-08 | X11: =0.301*(W11^(1/5)) -> 0.011532915 | Y11: =X11/W11 -> 139661.3 | Z11: =2*M11*E11*Y11/Q11 -> 0.054196755 | AA11: =D11*E11-Z11 -> 0.74380325 | AB11: =AA11/D11 -> 0.37190162 | AC11: =(T11*(D11+2*E11)-X11*2*E11/8)/D11 -> 0.0078941758 | AD11: =1000*AC11*(Q11^2) -> 33.382448 | AE11: =AE$2*P11 -> 0.0573 | AF11: =1/(AC11^0.5) -> 11.255029 | AG11: =IF(AC11<(1/(Sheet1!BL10^2)),MPM!AF11,Sheet1!BL10) -> 11.255029 | AH11: =IF(AG11=AF11,AB11,Sheet1!BK10) -> 0.37190162 | AI11: =IF(AH11>AB11,"error","ok") -> ok | AJ11: =1/(AG11^2) -> 0.0078941758 | AK11: =L11*AJ11*(Q11^2) -> 33.382448 | AL11: =100*AK11/AD11 -> 100
B12: =+B11+1 -> 7 | C12: 1641 | D12: 2 | E12: 0.398 | F12: 0.00916 | G12: 28.65 | H12: 28.65 | I12: 1 | J12: 2.68 | K12: 988.9 | L12: 1000 | M12: 1e-06 | N12: =C12/1000 -> 1.641 | O12: =G12/1000 -> 0.02865 | P12: =H12/1000 -> 0.02865 | Q12: =N12/(E12*D12) -> 2.0615578 | R12: =L12*9.81*E12*F12 -> 35.764121 | S12: =D12*E12/(D12+2*E12) -> 0.28469242 | T12: =9.81*S12*F12/(Q12^2) -> 0.0060193467 | U12: =Q12*S12/M12 -> 586909.87 | V12: =T12/U12 -> 1.0255998e-08 | W12: =8*V12 -> 8.2047987e-08 | X12: =0.301*(W12^(1/5)) -> 0.01151808 | Y12: =X12/W12 -> 140382.24 | Z12: =2*M12*E12*Y12/Q12 -> 0.054203797 | AA12: =D12*E12-Z12 -> 0.7417962 | AB12: =AA12/D12 -> 0.3708981 | AC12: =(T12*(D12+2*E12)-X12*2*E12/8)/D12 -> 0.0078420222 | AD12: =1000*AC12*(Q12^2) -> 33.328755 | AE12: =AE$2*P12 -> 0.0573 | AF12: =1/(AC12^0.5) -> 11.292393 | AG12: =IF(AC12<(1/(Sheet1!BL11^2)),MPM!AF12,Sheet1!BL11) -> 11.292393 | AH12: =IF(AG12=AF12,AB12,Sheet1!BK11) -> 0.3708981 | AI12: =IF(AH12>AB12,"error","ok") -> ok | AJ12: =1/(AG12^2) -> 0.0078420222 | AK12: =L12*AJ12*(Q12^2) -> 33.328755 | AL12: =100*AK12/AD12 -> 100
B13: =+B12+1 -> 8 | C13: 1641 | D13: 2 | E13: 0.368 | F13: 0.01373 | G13: 28.65 | H13: 28.65 | I13: 1 | J13: 2.68 | K13: 3828 | L13: 1000 | M13: 1e-06 | N13: =C13/1000 -> 1.641 | O13: =G13/1000 -> 0.02865 | P13: =H13/1000 -> 0.02865 | Q13: =N13/(E13*D13) -> 2.2296196 | R13: =L13*9.81*E13*F13 -> 49.566398 | S13: =D13*E13/(D13+2*E13) -> 0.26900585 | T13: =9.81*S13*F13/(Q13^2) -> 0.0072885264 | U13: =Q13*S13/M13 -> 599780.7 | V13: =T13/U13 -> 1.2151986e-08 | W13: =8*V13 -> 9.7215884e-08 | X13: =0.301*(W13^(1/5)) -> 0.011915546 | Y13: =X13/W13 -> 122567.89 | Z13: =2*M13*E13*Y13/Q13 -> 0.040459802 | AA13: =D13*E13-Z13 -> 0.6955402 | AB13: =AA13/D13 -> 0.3477701 | AC13: =(T13*(D13+2*E13)-X13*2*E13/8)/D13 -> 0.009422589 | AD13: =1000*AC13*(Q13^2) -> 46.841607 | AE13: =AE$2*P13 -> 0.0573 | AF13: =1/(AC13^0.5) -> 10.301842 | AG13: =IF(AC13<(1/(Sheet1!BL12^2)),MPM!AF13,Sheet1!BL12) -> 10.776673 | AH13: =IF(AG13=AF13,AB13,Sheet1!BK12) -> 0.31779907 | AI13: =IF(AH13>AB13,"error","ok") -> ok | AJ13: =1/(AG13^2) -> 0.0086105448 | AK13: =L13*AJ13*(Q13^2) -> 42.80477 | AL13: =100*AK13/AD13 -> 91.381941
B14: =+B13+1 -> 9 | C14: 1641 | D14: 2 | E14: 0.413 | F14: 0.0082 | G14: 28.65 | H14: 28.65 | I14: 1 | J14: 2.68 | K14: 496 | L14: 1000 | M14: 1e-06 | N14: =C14/1000 -> 1.641 | O14: =G14/1000 -> 0.02865 | P14: =H14/1000 -> 0.02865 | Q14: =N14/(E14*D14) -> 1.9866828 | R14: =L14*9.81*E14*F14 -> 33.222546 | S14: =D14*E14/(D14+2*E14) -> 0.29228592 | T14: =9.81*S14*F14/(Q14^2) -> 0.0059570834 | U14: =Q14*S14/M14 -> 580679.41 | V14: =T14/U14 -> 1.0258816e-08 | W14: =8*V14 -> 8.2070531e-08 | X14: =0.301*(W14^(1/5)) -> 0.011518713 | Y14: =X14/W14 -> 140351.38 | Z14: =2*M14*E14*Y14/Q14 -> 0.058353675 | AA14: =D14*E14-Z14 -> 0.76764632 | AB14: =AA14/D14 -> 0.38382316 | AC14: =(T14*(D14+2*E14)-X14*2*E14/8)/D14 -> 0.0078227053 | AD14: =1000*AC14*(Q14^2) -> 30.875503 | AE14: =AE$2*P14 -> 0.0573 | AF14: =1/(AC14^0.5) -> 11.306326 | AG14: =IF(AC14<(1/(Sheet1!BL13^2)),MPM!AF14,Sheet1!BL13) -> 11.306326 | AH14: =IF(AG14=AF14,AB14,Sheet1!BK13) -> 0.38382316 | AI14: =IF(AH14>AB14,"error","ok") -> ok | AJ14: =1/(AG14^2) -> 0.0078227053 | AK14: =L14*AJ14*(Q14^2) -> 30.875503 | AL14: =100*AK14/AD14 -> 100
B15: =+B14+1 -> 10 | C15: 1641 | D15: 2 | E15: 0.418 | F15: 0.00761 | G15: 28.65 | H15: 28.65 | I15: 1 | J15: 2.68 | K15: 320.5 | L15: 1000 | M15: 1e-06 | N15: =C15/1000 -> 1.641 | O15: =G15/1000 -> 0.02865 | P15: =H15/1000 -> 0.02865 | Q15: =N15/(E15*D15) -> 1.9629187 | R15: =L15*9.81*E15*F15 -> 31.205414 | S15: =D15*E15/(D15+2*E15) -> 0.29478138 | T15: =9.81*S15*F15/(Q15^2) -> 0.0057114859 | U15: =Q15*S15/M15 -> 578631.88 | V15: =T15/U15 -> 9.8706727e-09 | W15: =8*V15 -> 7.8965382e-08 | X15: =0.301*(W15^(1/5)) -> 0.0114302 | Y15: =X15/W15 -> 144749.51 | Z15: =2*M15*E15*Y15/Q15 -> 0.061648296 | AA15: =D15*E15-Z15 -> 0.7743517 | AB15: =AA15/D15 -> 0.38717585 | AC15: =(T15*(D15+2*E15)-X15*2*E15/8)/D15 -> 0.007501659 | AD15: =1000*AC15*(Q15^2) -> 28.904265 | AE15: =AE$2*P15 -> 0.0573 | AF15: =1/(AC15^0.5) -> 11.545728 | AG15: =IF(AC15<(1/(Sheet1!BL14^2)),MPM!AF15,Sheet1!BL14) -> 11.545728 | AH15: =IF(AG15=AF15,AB15,Sheet1!BK14) -> 0.38717585 | AI15: =IF(AH15>AB15,"error","ok") -> ok | AJ15: =1/(AG15^2) -> 0.007501659 | AK15: =L15*AJ15*(Q15^2) -> 28.904265 | AL15: =100*AK15/AD15 -> 100
B16: =+B15+1 -> 11 | C16: 1641 | D16: 2 | E16: 0.455 | F16: 0.00561 | G16: 28.65 | H16: 28.65 | I16: 1 | J16: 2.68 | K16: 31.9 | L16: 1000 | M16: 1e-06 | N16: =C16/1000 -> 1.641 | O16: =G16/1000 -> 0.02865 | P16: =H16/1000 -> 0.02865 | Q16: =N16/(E16*D16) -> 1.8032967 | R16: =L16*9.81*E16*F16 -> 25.040516 | S16: =D16*E16/(D16+2*E16) -> 0.31271478 | T16: =9.81*S16*F16/(Q16^2) -> 0.0052923175 | U16: =Q16*S16/M16 -> 563917.53 | V16: =T16/U16 -> 9.3849141e-09 | W16: =8*V16 -> 7.5079313e-08 | X16: =0.301*(W16^(1/5)) -> 0.011315417 | Y16: =X16/W16 -> 150712.84 | Z16: =2*M16*E16*Y16/Q16 -> 0.076054422 | AA16: =D16*E16-Z16 -> 0.83394558 | AB16: =AA16/D16 -> 0.41697279 | AC16: =(T16*(D16+2*E16)-X16*2*E16/8)/D16 -> 0.0070567577 | AD16: =1000*AC16*(Q16^2) -> 22.947722 | AE16: =AE$2*P16 -> 0.0573 | AF16: =1/(AC16^0.5) -> 11.904123 | AG16: =IF(AC16<(1/(Sheet1!BL15^2)),MPM!AF16,Sheet1!BL15) -> 11.904123 | AH16: =IF(AG16=AF16,AB16,Sheet1!BK15) -> 0.41697279 | AI16: =IF(AH16>AB16,"error","ok") -> ok | AJ16: =1/(AG16^2) -> 0.0070567577 | AK16: =L16*AJ16*(Q16^2) -> 22.947722 | AL16: =100*AK16/AD16 -> 100
B17: =+B16+1 -> 12 | C17: 1641 | D17: 2 | E17: 0.342 | F17: 0.01769 | G17: 28.65 | H17: 28.65 | I17: 1 | J17: 2.68 | K17: 8373.8 | L17: 1000 | M17: 1e-06 | N17: =C17/1000 -> 1.641 | O17: =G17/1000 -> 0.02865 | P17: =H17/1000 -> 0.02865 | Q17: =N17/(E17*D17) -> 2.3991228 | R17: =L17*9.81*E17*F17 -> 59.350304 | S17: =D17*E17/(D17+2*E17) -> 0.25484352 | T17: =9.81*S17*F17/(Q17^2) -> 0.0076836128 | U17: =Q17*S17/M17 -> 611400.89 | V17: =T17/U17 -> 1.2567225e-08 | W17: =8*V17 -> 1.005378e-07 | X17: =0.301*(W17^(1/5)) -> 0.011995887 | Y17: =X17/W17 -> 119317.18 | Z17: =2*M17*E17*Y17/Q17 -> 0.03401783 | AA17: =D17*E17-Z17 -> 0.64998217 | AB17: =AA17/D17 -> 0.32499108 | AC17: =(T17*(D17+2*E17)-X17*2*E17/8)/D17 -> 0.0097985842 | AD17: =1000*AC17*(Q17^2) -> 56.398595 | AE17: =AE$2*P17 -> 0.0573 | AF17: =1/(AC17^0.5) -> 10.102255 | AG17: =IF(AC17<(1/(Sheet1!BL16^2)),MPM!AF17,Sheet1!BL16) -> 10.633664 | AH17: =IF(AG17=AF17,AB17,Sheet1!BK16) -> 0.29332036 | AI17: =IF(AH17>AB17,"error","ok") -> ok | AJ17: =1/(AG17^2) -> 0.0088437019 | AK17: =L17*AJ17*(Q17^2) -> 50.902493 | AL17: =100*AK17/AD17 -> 90.254896
B18: =+B17+1 -> 13 | C18: 3271 | D18: 2 | E18: 0.597 | F18: 0.01219 | G18: 28.65 | H18: 28.65 | I18: 1 | J18: 2.68 | K18: 8469.5 | L18: 1000 | M18: 1e-06 | N18: =C18/1000 -> 3.271 | O18: =G18/1000 -> 0.02865 | P18: =H18/1000 -> 0.02865 | Q18: =N18/(E18*D18) -> 2.739531 | R18: =L18*9.81*E18*F18 -> 71.391588 | S18: =D18*E18/(D18+2*E18) -> 0.37382592 | T18: =9.81*S18*F18/(Q18^2) -> 0.0059564801 | U18: =Q18*S18/M18 -> 1024107.7 | V18: =T18/U18 -> 5.8162633e-09 | W18: =8*V18 -> 4.6530107e-08 | X18: =0.301*(W18^(1/5)) -> 0.010282845 | Y18: =X18/W18 -> 220993.38 | Z18: =2*M18*E18*Y18/Q18 -> 0.09631798 | AA18: =D18*E18-Z18 -> 1.097682 | AB18: =AA18/D18 -> 0.54884101 | AC18: =(T18*(D18+2*E18)-X18*2*E18/8)/D18 -> 0.0087451413 | AD18: =1000*AC18*(Q18^2) -> 65.632548 | AE18: =AE$2*P18 -> 0.0573 | AF18: =1/(AC18^0.5) -> 10.693419 | AG18: =IF(AC18<(1/(Sheet1!BL17^2)),MPM!AF18,Sheet1!BL17) -> 11.516073 | AH18: =IF(AG18=AF18,AB18,Sheet1!BK17) -> 0.47322853 | AI18: =IF(AH18>AB18,"error","ok") -> ok | AJ18: =1/(AG18^2) -> 0.0075403446 | AK18: =L18*AJ18*(Q18^2) -> 56.590513 | AL18: =100*AK18/AD18 -> 86.223245
... B59: =+B58+1 -> 54 | C59: 82.1 | D59: 0.354 | E59: 0.248 | F59: 0.00318 | G59: 5.21 | H59: 5.21 | I59: 1 | J59: 2.68 | K59: 3.8 | L59: 1000 | M59: 1e-06 | N59: =C59/1000 -> 0.0821 | O59: =G59/1000 -> 0.00521 | P59: =H59/1000 -> 0.00521 | Q59: =N59/(E59*D59) -> 0.93516494 | R59: =L59*9.81*E59*F59 -> 7.7365584 | S59: =D59*E59/(D59+2*E59) -> 0.10328471 | T59: =9.81*S59*F59/(Q59^2) -> 0.0036843062 | U59: =Q59*S59/M59 -> 96588.235 | V59: =T59/U59 -> 3.8144461e-08 | W59: =8*V59 -> 3.0515569e-07 | X59: =0.301*(W59^(1/5)) -> 0.014978585 | Y59: =X59/W59 -> 49085.059 | Z59: =2*M59*E59*Y59/Q59 -> 0.026034113 | AA59: =D59*E59-Z59 -> 0.061757887 | AB59: =AA59/D59 -> 0.17445731 | AC59: =(T59*(D59+2*E59)-X59*2*E59/8)/D59 -> 0.0062231299 | AD59: =1000*AC59*(Q59^2) -> 5.4423353 | AE59: =AE$2*P59 -> 0.01042 | AF59: =1/(AC59^0.5) -> 12.676389 | AG59: =IF(AC59<(1/(Sheet1!BL58^2)),MPM!AF59,Sheet1!BL58) -> 12.885175 | AH59: =IF(AG59=AF59,AB59,Sheet1!BK58) -> 0.16884944 | AI59: =IF(AH59>AB59,"error","ok") -> ok | AJ59: =1/(AG59^2) -> 0.0060230896 | AK59: =L59*AJ59*(Q59^2) -> 5.2673934 | AL59: =100*AK59/AD59 -> 96.785536
B60: 55 | C60: 10 | D60: 0.354 | E60: 0.077 | F60: 0.00175 | G60: 5.21 | H60: 5.21 | I60: 1 | J60: 1.25 | K60: 4.2 | L60: 1000 | M60: 1e-06 | N60: =C60/1000 -> 0.01 | O60: =G60/1000 -> 0.00521 | P60: =H60/1000 -> 0.00521 | Q60: =N60/(E60*D60) -> 0.36686477 | R60: =L60*9.81*E60*F60 -> 1.3218975 | S60: =D60*E60/(D60+2*E60) -> 0.05365748 | T60: =9.81*S60*F60/(Q60^2) -> 0.0068442412 | U60: =Q60*S60/M60 -> 19685.039 | V60: =T60/U60 -> 3.4768745e-07 | W60: =8*V60 -> 2.7814996e-06 | X60: =0.301*(W60^(1/5)) -> 0.023303561 | Y60: =X60/W60 -> 8378.0566 | Z60: =2*M60*E60*Y60/Q60 -> 0.0035168836 | AA60: =D60*E60-Z60 -> 0.023741116 | AB60: =AA60/D60 -> 0.0670653 | AC60: =(T60*(D60+2*E60)-X60*2*E60/8)/D60 -> 0.008554466 | AD60: =1000*AC60*(Q60^2) -> 1.1513435 | AE60: =AE$2*P60 -> 0.01042 | AF60: =1/(AC60^0.5) -> 10.811938 | AG60: =IF(AC60<(1/(Sheet1!BL59^2)),MPM!AF60,Sheet1!BL59) -> 10.987994 | AH60: =IF(AG60=AF60,AB60,Sheet1!BK59) -> 0.064933398 | AI60: =IF(AH60>AB60,"error","ok") -> ok | AJ60: =1/(AG60^2) -> 0.0082825327 | AK60: =L60*AJ60*(Q60^2) -> 1.1147441 | AL60: =100*AK60/AD60 -> 96.821154
B61: =+B60+1 -> 56 | C61: 10 | D61: 0.354 | E61: 0.063 | F61: 0.00326 | G61: 5.21 | H61: 5.21 | I61: 1 | J61: 1.25 | K61: 27.3 | L61: 1000 | M61: 1e-06 | N61: =C61/1000 -> 0.01 | O61: =G61/1000 -> 0.00521 | P61: =H61/1000 -> 0.00521 | Q61: =N61/(E61*D61) -> 0.44839028 | R61: =L61*9.81*E61*F61 -> 2.0147778 | S61: =D61*E61/(D61+2*E61) -> 0.0464625 | T61: =9.81*S61*F61/(Q61^2) -> 0.0073905508 | U61: =Q61*S61/M61 -> 20833.333 | V61: =T61/U61 -> 3.5474644e-07 | W61: =8*V61 -> 2.8379715e-06 | X61: =0.301*(W61^(1/5)) -> 0.023397427 | Y61: =X61/W61 -> 8244.4193 | Z61: =2*M61*E61*Y61/Q61 -> 0.0023167247 | AA61: =D61*E61-Z61 -> 0.019985275 | AB61: =AA61/D61 -> 0.05645558 | AC61: =(T61*(D61+2*E61)-X61*2*E61/8)/D61 -> 0.0089800986 | AD61: =1000*AC61*(Q61^2) -> 1.8054833 | AE61: =AE$2*P61 -> 0.01042 | AF61: =1/(AC61^0.5) -> 10.552599 | AG61: =IF(AC61<(1/(Sheet1!BL60^2)),MPM!AF61,Sheet1!BL60) -> 10.688912 | AH61: =IF(AG61=AF61,AB61,Sheet1!BK60) -> 0.055024832 | AI61: =IF(AH61>AB61,"error","ok") -> ok | AJ61: =1/(AG61^2) -> 0.0087525169 | AK61: =L61*AJ61*(Q61^2) -> 1.7597272 | AL61: =100*AK61/AD61 -> 97.465711
B62: =+B61+1 -> 57 | C62: 10 | D62: 0.354 | E62: 0.058 | F62: 0.00427 | G62: 5.21 | H62: 5.21 | I62: 1 | J62: 1.25 | K62: 48.1 | L62: 1000 | M62: 1e-06 | N62: =C62/1000 -> 0.01 | O62: =G62/1000 -> 0.00521 | P62: =H62/1000 -> 0.00521 | Q62: =N62/(E62*D62) -> 0.48704461 | R62: =L62*9.81*E62*F62 -> 2.4295446 | S62: =D62*E62/(D62+2*E62) -> 0.043685106 | T62: =9.81*S62*F62/(Q62^2) -> 0.0077142337 | U62: =Q62*S62/M62 -> 21276.596 | V62: =T62/U62 -> 3.6256898e-07 | W62: =8*V62 -> 2.9005519e-06 | X62: =0.301*(W62^(1/5)) -> 0.023499716 | Y62: =X62/W62 -> 8101.8087 | Z62: =2*M62*E62*Y62/Q62 -> 0.0019296175 | AA62: =D62*E62-Z62 -> 0.018602382 | AB62: =AA62/D62 -> 0.052549103 | AC62: =(T62*(D62+2*E62)-X62*2*E62/8)/D62 -> 0.0092795027 | AD62: =1000*AC62*(Q62^2) -> 2.2012136 | AE62: =AE$2*P62 -> 0.01042 | AF62: =1/(AC62^0.5) -> 10.380963 | AG62: =IF(AC62<(1/(Sheet1!BL61^2)),MPM!AF62,Sheet1!BL61) -> 10.550192 | AH62: =IF(AG62=AF62,AB62,Sheet1!BK61) -> 0.050876808 | AI62: =IF(AH62>AB62,"error","ok") -> ok | AJ62: =1/(AG62^2) -> 0.0089841967 | AK62: =L62*AJ62*(Q62^2) -> 2.1311633 | AL62: =100*AK62/AD62 -> 96.817653
B63: =+B62+1 -> 58 | C63: 5 | D63: 0.354 | E63: 0.033 | F63: 0.00697 | G63: 5.21 | H63: 5.21 | I63: 1 | J63: 1.25 | K63: 48.5 | L63: 1000 | M63: 1e-06 | N63: =C63/1000 -> 0.005 | O63: =G63/1000 -> 0.00521 | P63: =H63/1000 -> 0.00521 | Q63: =N63/(E63*D63) -> 0.4280089 | R63: =L63*9.81*E63*F63 -> 2.2563981 | S63: =D63*E63/(D63+2*E63) -> 0.027814286 | T63: =9.81*S63*F63/(Q63^2) -> 0.010381595 | U63: =Q63*S63/M63 -> 11904.762 | V63: =T63/U63 -> 8.72054e-07 | W63: =8*V63 -> 6.976432e-06 | X63: =0.301*(W63^(1/5)) -> 0.028008714 | Y63: =X63/W63 -> 4014.762 | Z63: =2*M63*E63*Y63/Q63 -> 0.00061908593 | AA63: =D63*E63-Z63 -> 0.011062914 | AB63: =AA63/D63 -> 0.03125117 | AC63: =(T63*(D63+2*E63)-X63*2*E63/8)/D63 -> 0.011664401 | AD63: =1000*AC63*(Q63^2) -> 2.1368206 | AE63: =AE$2*P63 -> 0.01042 | AF63: =1/(AC63^0.5) -> 9.2590999 | AG63: =IF(AC63<(1/(Sheet1!BL62^2)),MPM!AF63,Sheet1!BL62) -> 9.6079509 | AH63: =IF(AG63=AF63,AB63,Sheet1!BK62) -> 0.029022998 | AI63: =IF(AH63>AB63,"error","ok") -> ok | AJ63: =1/(AG63^2) -> 0.010832743 | AK63: =L63*AJ63*(Q63^2) -> 1.9844678 | AL63: =100*AK63/AD63 -> 92.870116
B64: =+B63+1 -> 59 | C64: 21.6 | D64: 0.354 | E64: 0.117 | F64: 0.0028 | G64: 5.21 | H64: 5.21 | I64: 1 | J64: 1.25 | K64: 49.4 | L64: 1000 | M64: 1e-06 | N64: =C64/1000 -> 0.0216 | O64: =G64/1000 -> 0.00521 | P64: =H64/1000 -> 0.00521 | Q64: =N64/(E64*D64) -> 0.52151239 | R64: =L64*9.81*E64*F64 -> 3.213756 | S64: =D64*E64/(D64+2*E64) -> 0.070438776 | T64: =9.81*S64*F64/(Q64^2) -> 0.0071139299 | U64: =Q64*S64/M64 -> 36734.694 | V64: =T64/U64 -> 1.9365698e-07 | W64: =8*V64 -> 1.5492558e-06 | X64: =0.301*(W64^(1/5)) -> 0.02072961 | Y64: =X64/W64 -> 13380.366 | Z64: =2*M64*E64*Y64/Q64 -> 0.0060037032 | AA64: =D64*E64-Z64 -> 0.035414297 | AB64: =AA64/D64 -> 0.10004039 | AC64: =(T64*(D64+2*E64)-X64*2*E64/8)/D64 -> 0.01010353 | AD64: =1000*AC64*(Q64^2) -> 2.7479093 | AE64: =AE$2*P64 -> 0.01042 | AF64: =1/(AC64^0.5) -> 9.9486334 | AG64: =IF(AC64<(1/(Sheet1!BL63^2)),MPM!AF64,Sheet1!BL63) -> 11.313398 | AH64: =IF(AG64=AF64,AB64,Sheet1!BK63) -> 0.077359929 | AI64: =IF(AH64>AB64,"error","ok") -> ok | AJ64: =1/(AG64^2) -> 0.0078129285 | AK64: =L64*AJ64*(Q64^2) -> 2.1249225 | AL64: =100*AK64/AD64 -> 77.328699
B65: =+B64+1 -> 60 | C65: 5 | D65: 0.354 | E65: 0.046 | F65: 0.00217 | G65: 5.21 | H65: 5.21 | I65: 1 | J65: 1.25 | K65: 1.1 | L65: 1000 | M65: 1e-06 | N65: =C65/1000 -> 0.005 | O65: =G65/1000 -> 0.00521 | P65: =H65/1000 -> 0.00521 | Q65: =N65/(E65*D65) -> 0.30704986 | R65: =L65*9.81*E65*F65 -> 0.9792342 | S65: =D65*E65/(D65+2*E65) -> 0.036511211 | T65: =9.81*S65*F65/(Q65^2) -> 0.0082439843 | U65: =Q65*S65/M65 -> 11210.762 | V65: =T65/U65 -> 7.353634e-07 | W65: =8*V65 -> 5.8829072e-06 | X65: =0.301*(W65^(1/5)) -> 0.027069791 | Y65: =X65/W65 -> 4601.4308 | Z65: =2*M65*E65*Y65/Q65 -> 0.0013787065 | AA65: =D65*E65-Z65 -> 0.014905294 | AB65: =AA65/D65 -> 0.042105349 | AC65: =(T65*(D65+2*E65)-X65*2*E65/8)/D65 -> 0.0095071028 | AD65: =1000*AC65*(Q65^2) -> 0.89632604 | AE65: =AE$2*P65 -> 0.01042 | AF65: =1/(AC65^0.5) -> 10.25595 | AG65: =IF(AC65<(1/(Sheet1!BL64^2)),MPM!AF65,Sheet1!BL64) -> 10.25595 | AH65: =IF(AG65=AF65,AB65,Sheet1!BK64) -> 0.042105349 | AI65: =IF(AH65>AB65,"error","ok") -> ok | AJ65: =1/(AG65^2) -> 0.0095071028 | AK65: =L65*AJ65*(Q65^2) -> 0.89632604 | AL65: =100*AK65/AD65 -> 100
B66: =+B65+1 -> 61 | C66: 10 | D66: 0.354 | E66: 0.082 | F66: 0.00128 | G66: 5.21 | H66: 5.21 | I66: 1 | J66: 1.25 | K66: 1.1 | L66: 1000 | M66: 1e-06 | N66: =C66/1000 -> 0.01 | O66: =G66/1000 -> 0.00521 | P66: =H66/1000 -> 0.00521 | Q66: =N66/(E66*D66) -> 0.34449497 | R66: =L66*9.81*E66*F66 -> 1.0296576 | S66: =D66*E66/(D66+2*E66) -> 0.05603861 | T66: =9.81*S66*F66/(Q66^2) -> 0.0059292609 | U66: =Q66*S66/M66 -> 19305.019 | V66: =T66/U66 -> 3.0713571e-07 | W66: =8*V66 -> 2.4570857e-06 | X66: =0.301*(W66^(1/5)) -> 0.022732676 | Y66: =X66/W66 -> 9251.8855 | Z66: =2*M66*E66*Y66/Q66 -> 0.0044044452 | AA66: =D66*E66-Z66 -> 0.024623555 | AB66: =AA66/D66 -> 0.069558064 | AC66: =(T66*(D66+2*E66)-X66*2*E66/8)/D66 -> 0.0073597099 | AD66: =1000*AC66*(Q66^2) -> 0.8734267 | AE66: =AE$2*P66 -> 0.01042 | AF66: =1/(AC66^0.5) -> 11.65654 | AG66: =IF(AC66<(1/(Sheet1!BL65^2)),MPM!AF66,Sheet1!BL65) -> 11.65654 | AH66: =IF(AG66=AF66,AB66,Sheet1!BK65) -> 0.069558064 | AI66: =IF(AH66>AB66,"error","ok") -> ok | AJ66: =1/(AG66^2) -> 0.0073597099 | AK66: =L66*AJ66*(Q66^2) -> 0.8734267 | AL66: =100*AK66/AD66 -> 100
B67: =+B66+1 -> 62 | C67: 10 | D67: 0.354 | E67: 0.051 | F67: 0.00638 | G67: 5.21 | H67: 5.21 | I67: 1 | J67: 1.25 | K67: 106.7 | L67: 1000 | M67: 1e-06 | N67: =C67/1000 -> 0.01 | O67: =G67/1000 -> 0.00521 | P67: =H67/1000 -> 0.00521 | Q67: =N67/(E67*D67) -> 0.55389387 | R67: =L67*9.81*E67*F67 -> 3.1919778 | S67: =D67*E67/(D67+2*E67) -> 0.039592105 | T67: =9.81*S67*F67/(Q67^2) -> 0.0080769084 | U67: =Q67*S67/M67 -> 21929.825 | V67: =T67/U67 -> 3.6830702e-07 | W67: =8*V67 -> 2.9464562e-06 | X67: =0.301*(W67^(1/5)) -> 0.023573632 | Y67: =X67/W67 -> 8000.6727 | Z67: =2*M67*E67*Y67/Q67 -> 0.0014733303 | AA67: =D67*E67-Z67 -> 0.01658067 | AB67: =AA67/D67 -> 0.04683805 | AC67: =(T67*(D67+2*E67)-X67*2*E67/8)/D67 -> 0.0095551029 | AD67: =1000*AC67*(Q67^2) -> 2.9314905 | AE67: =AE$2*P67 -> 0.01042 | AF67: =1/(AC67^0.5) -> 10.230157 | AG67: =IF(AC67<(1/(Sheet1!BL66^2)),MPM!AF67,Sheet1!BL66) -> 10.361574 | AH67: =IF(AG67=AF67,AB67,Sheet1!BK66) -> 0.045657484 | AI67: =IF(AH67>AB67,"error","ok") -> ok | AJ67: =1/(AG67^2) -> 0.009314264 | AK67: =L67*AJ67*(Q67^2) -> 2.8576015 | AL67: =100*AK67/AD67 -> 97.479473
B68: =+B67+1 -> 63 | C68: 21.6 | D68: 0.354 | E68: 0.098 | F68: 0.00391 | G68: 5.21 | H68: 5.21 | I68: 1 | J68: 1.25 | K68: 109 | L68: 1000 | M68: 1e-06 | N68: =C68/1000 -> 0.0216 | O68: =G68/1000 -> 0.00521 | P68: =H68/1000 -> 0.00521 | Q68: =N68/(E68*D68) -> 0.62262193 | R68: =L68*9.81*E68*F68 -> 3.7589958 | S68: =D68*E68/(D68+2*E68) -> 0.063076364 | T68: =9.81*S68*F68/(Q68^2) -> 0.0062411351 | U68: =Q68*S68/M68 -> 39272.727 | V68: =T68/U68 -> 1.5891779e-07 | W68: =8*V68 -> 1.2713423e-06 | X68: =0.301*(W68^(1/5)) -> 0.019925948 | Y68: =X68/W68 -> 15673.157 | Z68: =2*M68*E68*Y68/Q68 -> 0.004933875 | AA68: =D68*E68-Z68 -> 0.029758125 | AB68: =AA68/D68 -> 0.0840625 | AC68: =(T68*(D68+2*E68)-X68*2*E68/8)/D68 -> 0.0083176231 | AD68: =1000*AC68*(Q68^2) -> 3.2243937 | AE68: =AE$2*P68 -> 0.01042 | AF68: =1/(AC68^0.5) -> 10.964792 | AG68: =IF(AC68<(1/(Sheet1!BL67^2)),MPM!AF68,Sheet1!BL67) -> 11.342419 | AH68: =IF(AG68=AF68,AB68,Sheet1!BK67) -> 0.078558231 | AI68: =IF(AH68>AB68,"error","ok") -> ok | AJ68: =1/(AG68^2) -> 0.0077729994 | AK68: =L68*AJ68*(Q68^2) -> 3.0132659 | AL68: =100*AK68/AD68 -> 93.452171
B69: =+B68+1 -> 64 | C69: 2.1 | D69: 0.354 | E69: 0.024 | F69: 0.00572 | G69: 5.21 | H69: 5.21 | I69: 1 | J69: 1.25 | K69: 4.4 | L69: 1000 | M69: 1e-06 | N69: =C69/1000 -> 0.0021 | O69: =G69/1000 -> 0.00521 | P69: =H69/1000 -> 0.00521 | Q69: =N69/(E69*D69) -> 0.24717514 | R69: =L69*9.81*E69*F69 -> 1.3467168 | S69: =D69*E69/(D69+2*E69) -> 0.021134328 | T69: =9.81*S69*F69/(Q69^2) -> 0.019410821 | U69: =Q69*S69/M69 -> 5223.8806 | V69: =T69/U69 -> 3.7157857e-06 | W69: =8*V69 -> 2.9726286e-05 | X69: =0.301*(W69^(1/5)) -> 0.037427828 | Y69: =X69/W69 -> 1259.0819 | Z69: =2*M69*E69*Y69/Q69 -> 0.00024450651 | AA69: =D69*E69-Z69 -> 0.0082514935 | AB69: =AA69/D69 -> 0.023309304 | AC69: =(T69*(D69+2*E69)-X69*2*E69/8)/D69 -> 0.021408427 | AD69: =1000*AC69*(Q69^2) -> 1.3079596 | AE69: =AE$2*P69 -> 0.01042 | AF69: =1/(AC69^0.5) -> 6.8345138 | AG69: =IF(AC69<(1/(Sheet1!BL68^2)),MPM!AF69,Sheet1!BL68) -> 8.5851595 | AH69: =IF(AG69=AF69,AB69,Sheet1!BK68) -> 0.01477229 | AI69: =IF(AH69>AB69,"error","ok") -> ok | AJ69: =1/(AG69^2) -> 0.013567607 | AK69: =L69*AJ69*(Q69^2) -> 0.82892044 | AL69: =100*AK69/AD69 -> 63.375079
B70: =+B69+1 -> 65 | C70: 1.1 | D70: 0.354 | E70: 0.013 | F70: 0.00791 | G70: 5.21 | H70: 5.21 | I70: 1 | J70: 1.25 | K70: 4.4 | L70: 1000 | M70: 1e-06 | N70: =C70/1000 -> 0.0011 | O70: =G70/1000 -> 0.00521 | P70: =H70/1000 -> 0.00521 | Q70: =N70/(E70*D70) -> 0.23902651 | R70: =L70*9.81*E70*F70 -> 1.0087623 | S70: =D70*E70/(D70+2*E70) -> 0.012110526 | T70: =9.81*S70*F70/(Q70^2) -> 0.016448124 | U70: =Q70*S70/M70 -> 2894.7368 | V70: =T70/U70 -> 5.6820791e-06 | W70: =8*V70 -> 4.5456633e-05 | X70: =0.301*(W70^(1/5)) -> 0.040746091 | Y70: =X70/W70 -> 896.37283 | Z70: =2*M70*E70*Y70/Q70 -> 9.7502547e-05 | AA70: =D70*E70-Z70 -> 0.0045044975 | AB70: =AA70/D70 -> 0.012724569 | AC70: =(T70*(D70+2*E70)-X70*2*E70/8)/D70 -> 0.017282097 | AD70: =1000*AC70*(Q70^2) -> 0.98738966 | AE70: =AE$2*P70 -> 0.01042 | AF70: =1/(AC70^0.5) -> 7.6067962 | AG70: =IF(AC70<(1/(Sheet1!BL69^2)),MPM!AF70,Sheet1!BL69) -> 8.1754399 | AH70: =IF(AG70=AF70,AB70,Sheet1!BK69) -> 0.011016012 | AI70: =IF(AH70>AB70,"error","ok") -> ok | AJ70: =1/(AG70^2) -> 0.01496159 | AK70: =L70*AJ70*(Q70^2) -> 0.85481056 | AL70: =100*AK70/AD70 -> 86.572768
B71: =+B70+1 -> 66 | C71: 0.8 | D71: 0.354 | E71: 0.008 | F71: 0.01063 | G71: 5.21 | H71: 5.21 | I71: 1 | J71: 1.25 | K71: 4.4 | L71: 1000 | M71: 1e-06 | N71: =C71/1000 -> 0.0008 | O71: =G71/1000 -> 0.00521 | P71: =H71/1000 -> 0.00521 | Q71: =N71/(E71*D71) -> 0.28248588 | R71: =L71*9.81*E71*F71 -> 0.8342424 | S71: =D71*E71/(D71+2*E71) -> 0.0076540541 | T71: =9.81*S71*F71/(Q71^2) -> 0.01000231 | U71: =Q71*S71/M71 -> 2162.1622 | V71: =T71/U71 -> 4.6260685e-06 | W71: =8*V71 -> 3.7008548e-05 | X71: =0.301*(W71^(1/5)) -> 0.039104515 | Y71: =X71/W71 -> 1056.6347 | Z71: =2*M71*E71*Y71/Q71 -> 5.9847788e-05 | AA71: =D71*E71-Z71 -> 0.0027721522 | AB71: =AA71/D71 -> 0.0078309385 | AC71: =(T71*(D71+2*E71)-X71*2*E71/8)/D71 -> 0.010233463 | AD71: =1000*AC71*(Q71^2) -> 0.81661261 | AE71: =AE$2*P71 -> 0.01042 | AF71: =1/(AC71^0.5) -> 9.8852737 | AG71: =IF(AC71<(1/(Sheet1!BL70^2)),MPM!AF71,Sheet1!BL70) -> 9.8852737 | AH71: =IF(AG71=AF71,AB71,Sheet1!BK70) -> 0.0078309385 | AI71: =IF(AH71>AB71,"error","ok") -> ok | AJ71: =1/(AG71^2) -> 0.010233463 | AK71: =L71*AJ71*(Q71^2) -> 0.81661261 | AL71: =100*AK71/AD71 -> 100
B72: =+B71+1 -> 67 | C72: 550 | D72: 2 | E72: 0.49 | F72: 0.0005 | G72: 0.41 | H72: 0.7 | I72: 3.5 | J72: 2.68 | K72: 17.4 | L72: 1000 | M72: 1e-06 | N72: =C72/1000 -> 0.55 | O72: =G72/1000 -> 0.00041 | P72: =H72/1000 -> 0.0007 | Q72: =N72/(E72*D72) -> 0.56122449 | R72: =L72*9.81*E72*F72 -> 2.40345 | S72: =D72*E72/(D72+2*E72) -> 0.32885906 | T72: =9.81*S72*F72/(Q72^2) -> 0.0051212455 | U72: =Q72*S72/M72 -> 184563.76 | V72: =T72/U72 -> 2.7747839e-08 | W72: =8*V72 -> 2.2198271e-07 | X72: =0.301*(W72^(1/5)) -> 0.014054983 | Y72: =X72/W72 -> 63315.665 | Z72: =2*M72*E72*Y72/Q72 -> 0.11056066 | AA72: =D72*E72-Z72 -> 0.86943934 | AB72: =AA72/D72 -> 0.43471967 | AC72: =(T72*(D72+2*E72)-X72*2*E72/8)/D72 -> 0.0067697881 | AD72: =1000*AC72*(Q72^2) -> 2.1323 | AE72: =AE$2*P72 -> 0.0014 | AF72: =1/(AC72^0.5) -> 12.153811 | AG72: =IF(AC72<(1/(Sheet1!BL71^2)),MPM!AF72,Sheet1!BL71) -> 18.367584 | AH72: =IF(AG72=AF72,AB72,Sheet1!BK71) -> 0.19034003 | AI72: =IF(AH72>AB72,"error","ok") -> ok | AJ72: =1/(AG72^2) -> 0.002964121 | AK72: =L72*AJ72*(Q72^2) -> 0.93361787 | AL72: =100*AK72/AD72 -> 43.784546
... B142: =+B141+1 -> 137 | C142: 100 | D142: 2 | E142: 0.068 | F142: 0.00812 | G142: 4.62 | H142: 9.4 | I142: 5.22 | J142: 2.68 | K142: 118.7 | L142: 1000 | M142: 1e-06 | N142: =C142/1000 -> 0.1 | O142: =G142/1000 -> 0.00462 | P142: =H142/1000 -> 0.0094 | Q142: =N142/(E142*D142) -> 0.73529412 | R142: =L142*9.81*E142*F142 -> 5.4166896 | S142: =D142*E142/(D142+2*E142) -> 0.063670412 | T142: =9.81*S142*F142/(Q142^2) -> 0.0093808137 | U142: =Q142*S142/M142 -> 46816.479 | V142: =T142/U142 -> 2.0037418e-07 | W142: =8*V142 -> 1.6029935e-06 | X142: =0.301*(W142^(1/5)) -> 0.020871461 | Y142: =X142/W142 -> 13020.303 | Z142: =2*M142*E142*Y142/Q142 -> 0.0024082353 | AA142: =D142*E142-Z142 -> 0.13359176 | AB142: =AA142/D142 -> 0.066795882 | AC142: =(T142*(D142+2*E142)-X142*2*E142/8)/D142 -> 0.0098413017 | AD142: =1000*AC142*(Q142^2) -> 5.320773 | AE142: =AE$2*P142 -> 0.0188 | AF142: =1/(AC142^0.5) -> 10.080306 | AG142: =IF(AC142<(1/(Sheet1!BL141^2)),MPM!AF142,Sheet1!BL141) -> 10.080306 | AH142: =IF(AG142=AF142,AB142,Sheet1!BK141) -> 0.066795882 | AI142: =IF(AH142>AB142,"error","ok") -> ok | AJ142: =1/(AG142^2) -> 0.0098413017 | AK142: =L142*AJ142*(Q142^2) -> 5.320773 | AL142: =100*AK142/AD142 -> 100

Sheet Sheet1
A3: ID | B3: Czbso | C3: rbso | D3: Czbsi | E3: error | F3: rbsi | G3: Czbsi | H3: error | I3: rbsi | J3: Czbsi | K3: error | L3: rbsi | M3: Czbsi | N3: error | O3: rbsi | P3: Czbsi | Q3: error | R3: rbsi | S3: Czbsi | T3: error | U3: rbsi | V3: Czbsi | W3: error | X3: rbsi | Y3: Czbsi | Z3: error | AA3: rbsi | AB3: Czbsi | AC3: error | AD3: rbsi | AE3: Czbsi | AF3: error | AG3: rbsi | AH3: Czbsi | AI3: error | AJ3: rbsi | AK3: Czbsi | AL3: error | AM3: rbsi | AN3: Czbsi | AO3: error | AP3: rbsi | AQ3: Czbsi | AR3: error | AS3: rbsi | AT3: Czbsi | AU3: error | AV3: rbsi | AW3: Czbsi | AX3: error | AY3: rbsi | AZ3: Czbsi | BA3: error | BB3: rbsi | BC3: Czbsi | BD3: error | BE3: rbsi | BF3: Czbsi | BG3: error | BH3: rbsi | BI3: Czbsi | BJ3: error | BK3: rbsi | BL3: Czbsi | BM3: error | BN3: error rb
B4: - | C4: m | D4: - | F4: m | G4: - | I4: m | J4: - | L4: m | M4: - | O4: m | P4: - | R4: m | S4: - | U4: m | V4: - | X4: m | Y4: - | AA4: m | AB4: - | AD4: m | AE4: - | AG4: m | AH4: - | AJ4: m | AK4: - | AM4: m | AN4: - | AP4: m | AQ4: - | AS4: m | AT4: - | AV4: m | AW4: - | AY4: m | AZ4: - | BB4: m | BC4: - | BE4: m | BF4: - | BH4: m | BI4: - | BK4: m | BL4: - | BN4: -
A5: =MPM!B6 -> 1 | B5: =1/(MPM!AC6^0.5) -> 10.864498 | C5: =(MPM!$Q6^2)/(9.81*MPM!$F6*(Sheet1!B5^2)) -> 0.36279651 | D5: =8.1*((C5/MPM!$AE6)^(1/6)) -> 11.017163 | E5: =100*ABS(D5-B5)/D5 -> 1.3856972 | F5: =(MPM!$Q6^2)/(9.81*MPM!$F6*(D5^2)) -> 0.35281165 | G5: =8.1*((F5/MPM!$AE6)^(1/6)) -> 10.966038 | H5: =100*ABS(G5-D5)/G5 -> 0.46621261 | I5: =(MPM!$Q6^2)/(9.81*MPM!$F6*(G5^2)) -> 0.35610903 | J5: =8.1*((I5/MPM!$AE6)^(1/6)) -> 10.983053 | K5: =100*ABS(J5-G5)/J5 -> 0.15492294 | L5: =(MPM!$Q6^2)/(9.81*MPM!$F6*(J5^2)) -> 0.35500649 | M5: =8.1*((L5/MPM!$AE6)^(1/6)) -> 10.977378 | N5: =100*ABS(M5-J5)/M5 -> 0.05169438 | O5: =(MPM!$Q6^2)/(9.81*MPM!$F6*(M5^2)) -> 0.35537363 | P5: =8.1*((O5/MPM!$AE6)^(1/6)) -> 10.97927 | Q5: =100*ABS(P5-M5)/P5 -> 0.017225524 | R5: =(MPM!$Q6^2)/(9.81*MPM!$F6*(P5^2)) -> 0.35525121 | S5: =8.1*((R5/MPM!$AE6)^(1/6)) -> 10.978639 | T5: =100*ABS(S5-P5)/S5 -> 0.0057425008 | U5: =(MPM!$Q6^2)/(9.81*MPM!$F6*(S5^2)) -> 0.35529201 | V5: =8.1*((U5/MPM!$AE6)^(1/6)) -> 10.978849 | W5: =100*ABS(V5-S5)/V5 -> 0.0019140936 | X5: =(MPM!$Q6^2)/(9.81*MPM!$F6*(V5^2)) -> 0.35527841 | Y5: =8.1*((X5/MPM!$AE6)^(1/6)) -> 10.978779 | Z5: =100*ABS(Y5-V5)/Y5 -> 0.00063803936 | AA5: =(MPM!$Q6^2)/(9.81*MPM!$F6*(Y5^2)) -> 0.35528294 | AB5: =8.1*((AA5/MPM!$AE6)^(1/6)) -> 10.978803 | AC5: =100*ABS(AB5-Y5)/AB5 -> 0.00021267888 | AD5: =(MPM!$Q6^2)/(9.81*MPM!$F6*(AB5^2)) -> 0.35528143 | AE5: =8.1*((AD5/MPM!$AE6)^(1/6)) -> 10.978795 | AF5: =100*ABS(AE5-AB5)/AE5 -> 7.0893061e-05 | AG5: =(MPM!$Q6^2)/(9.81*MPM!$F6*(AE5^2)) -> 0.35528193 | AH5: =8.1*((AG5/MPM!$AE6)^(1/6)) -> 10.978797 | AI5: =100*ABS(AH5-AE5)/AH5 -> 2.3631009e-05 | AJ5: =(MPM!$Q6^2)/(9.81*MPM!$F6*(AH5^2)) -> 0.35528176 | AK5: =8.1*((AJ5/MPM!$AE6)^(1/6)) -> 10.978796 | AL5: =100*ABS(AK5-AH5)/AK5 -> 7.8770043e-06 | AM5: =(MPM!$Q6^2)/(9.81*MPM!$F6*(AK5^2)) -> 0.35528182 | AN5: =8.1*((AM5/MPM!$AE6)^(1/6)) -> 10.978797 | AO5: =100*ABS(AN5-AK5)/AN5 -> 2.625668e-06 | AP5: =(MPM!$Q6^2)/(9.81*MPM!$F6*(AN5^2)) -> 0.3552818 | AQ5: =8.1*((AP5/MPM!$AE6)^(1/6)) -> 10.978797 | AR5: =100*ABS(AQ5-AN5)/AQ5 -> 8.7522266e-07 | AS5: =(MPM!$Q6^2)/(9.81*MPM!$F6*(AQ5^2)) -> 0.35528181 | AT5: =8.1*((AS5/MPM!$AE6)^(1/6)) -> 10.978797 | AU5: =100*ABS(AT5-AQ5)/AT5 -> 2.9174088e-07 | AV5: =(MPM!$Q6^2)/(9.81*MPM!$F6*(AT5^2)) -> 0.35528181 | AW5: =8.1*((AV5/MPM!$AE6)^(1/6)) -> 10.978797 | AX5: =100*ABS(AW5-AT5)/AW5 -> 9.7246958e-08 | AY5: =(MPM!$Q6^2)/(9.81*MPM!$F6*(AW5^2)) -> 0.35528181 | AZ5: =8.1*((AY5/MPM!$AE6)^(1/6)) -> 10.978797 | BA5: =100*ABS(AZ5-AW5)/AZ5 -> 3.2415658e-08 | BB5: =(MPM!$Q6^2)/(9.81*MPM!$F6*(AZ5^2)) -> 0.35528181 | BC5: =8.1*((BB5/MPM!$AE6)^(1/6)) -> 10.978797 | BD5: =100*ABS(BC5-AZ5)/BC5 -> 1.0805219e-08 | BE5: =(MPM!$Q6^2)/(9.81*MPM!$F6*(BC5^2)) -> 0.35528181 | BF5: =8.1*((BE5/MPM!$AE6)^(1/6)) -> 10.978797 | BG5: =100*ABS(BF5-BC5)/BF5 -> 3.6017398e-09 | BH5: =(MPM!$Q6^2)/(9.81*MPM!$F6*(BF5^2)) -> 0.35528181 | BI5: =8.1*((BH5/MPM!$AE6)^(1/6)) -> 10.978797 | BJ5: =100*ABS(BI5-BF5)/BI5 -> 1.2005799e-09 | BK5: =(MPM!$Q6^2)/(9.81*MPM!$F6*(BI5^2)) -> 0.35528181 | BL5: =8.1*((BK5/MPM!$AE6)^(1/6)) -> 10.978797 | BM5: =100*ABS(BL5-BI5)/BL5 -> 4.0019331e-10 | BN5: =100*ABS(BK5-BH5)/BK5 -> 2.4011638e-09
A6: =MPM!B7 -> 2 | B6: =1/(MPM!AC7^0.5) -> 11.393645 | C6: =(MPM!$Q7^2)/(9.81*MPM!$F7*(Sheet1!B6^2)) -> 0.41003325 | D6: =8.1*((C6/MPM!$AE7)^(1/6)) -> 11.244214 | E6: =100*ABS(D6-B6)/D6 -> 1.3289639 | F6: =(MPM!$Q7^2)/(9.81*MPM!$F7*(D6^2)) -> 0.42100406 | G6: =8.1*((F6/MPM!$AE7)^(1/6)) -> 11.293805 | H6: =100*ABS(G6-D6)/G6 -> 0.43910331 | I6: =(MPM!$Q7^2)/(9.81*MPM!$F7*(G6^2)) -> 0.41731489 | J6: =8.1*((I6/MPM!$AE7)^(1/6)) -> 11.277251 | K6: =100*ABS(J6-G6)/J6 -> 0.14679771 | L6: =(MPM!$Q7^2)/(9.81*MPM!$F7*(J6^2)) -> 0.41854101 | M6: =8.1*((L6/MPM!$AE7)^(1/6)) -> 11.282766 | N6: =100*ABS(M6-J6)/M6 -> 0.048884736 | O6: =(MPM!$Q7^2)/(9.81*MPM!$F7*(M6^2)) -> 0.4181319 | P6: =8.1*((O6/MPM!$AE7)^(1/6)) -> 11.280927 | Q6: =100*ABS(P6-M6)/P6 -> 0.016300225 | R6: =(MPM!$Q7^2)/(9.81*MPM!$F7*(P6^2)) -> 0.41826823 | S6: =8.1*((R6/MPM!$AE7)^(1/6)) -> 11.28154 | T6: =100*ABS(S6-P6)/S6 -> 0.0054328178 | U6: =(MPM!$Q7^2)/(9.81*MPM!$F7*(S6^2)) -> 0.41822278 | V6: =8.1*((U6/MPM!$AE7)^(1/6)) -> 11.281336 | W6: =100*ABS(V6-S6)/V6 -> 0.0018110049 | X6: =(MPM!$Q7^2)/(9.81*MPM!$F7*(V6^2)) -> 0.41823793 | Y6: =8.1*((X6/MPM!$AE7)^(1/6)) -> 11.281404 | Z6: =100*ABS(Y6-V6)/Y6 -> 0.000603661 | AA6: =(MPM!$Q7^2)/(9.81*MPM!$F7*(Y6^2)) -> 0.41823288 | AB6: =8.1*((AA6/MPM!$AE7)^(1/6)) -> 11.281381 | AC6: =100*ABS(AB6-Y6)/AB6 -> 0.00020122114 | AD6: =(MPM!$Q7^2)/(9.81*MPM!$F7*(AB6^2)) -> 0.41823456 | AE6: =8.1*((AD6/MPM!$AE7)^(1/6)) -> 11.281389 | AF6: =100*ABS(AE6-AB6)/AE6 -> 6.7073625e-05 | AG6: =(MPM!$Q7^2)/(9.81*MPM!$F7*(AE6^2)) -> 0.418234 | AH6: =8.1*((AG6/MPM!$AE7)^(1/6)) -> 11.281386 | AI6: =100*ABS(AH6-AE6)/AH6 -> 2.2357885e-05 | AJ6: =(MPM!$Q7^2)/(9.81*MPM!$F7*(AH6^2)) -> 0.41823419 | AK6: =8.1*((AJ6/MPM!$AE7)^(1/6)) -> 11.281387 | AL6: =100*ABS(AK6-AH6)/AK6 -> 7.4526272e-06 | AM6: =(MPM!$Q7^2)/(9.81*MPM!$F7*(AK6^2)) -> 0.41823413 | AN6: =8.1*((AM6/MPM!$AE7)^(1/6)) -> 11.281387 | AO6: =100*ABS(AN6-AK6)/AN6 -> 2.4842092e-06 | AP6: =(MPM!$Q7^2)/(9.81*MPM!$F7*(AN6^2)) -> 0.41823415 | AQ6: =8.1*((AP6/MPM!$AE7)^(1/6)) -> 11.281387 | AR6: =100*ABS(AQ6-AN6)/AQ6 -> 8.2806969e-07 | AS6: =(MPM!$Q7^2)/(9.81*MPM!$F7*(AQ6^2)) -> 0.41823414 | AT6: =8.1*((AS6/MPM!$AE7)^(1/6)) -> 11.281387 | AU6: =100*ABS(AT6-AQ6)/AT6 -> 2.7602322e-07 | AV6: =(MPM!$Q7^2)/(9.81*MPM!$F7*(AT6^2)) -> 0.41823414 | AW6: =8.1*((AV6/MPM!$AE7)^(1/6)) -> 11.281387 | AX6: =100*ABS(AW6-AT6)/AW6 -> 9.2007719e-08 | AY6: =(MPM!$Q7^2)/(9.81*MPM!$F7*(AW6^2)) -> 0.41823414 | AZ6: =8.1*((AY6/MPM!$AE7)^(1/6)) -> 11.281387 | BA6: =100*ABS(AZ6-AW6)/AZ6 -> 3.0669235e-08 | BB6: =(MPM!$Q7^2)/(9.81*MPM!$F7*(AZ6^2)) -> 0.41823414 | BC6: =8.1*((BB6/MPM!$AE7)^(1/6)) -> 11.281387 | BD6: =100*ABS(BC6-AZ6)/BC6 -> 1.0223078e-08 | BE6: =(MPM!$Q7^2)/(9.81*MPM!$F7*(BC6^2)) -> 0.41823414 | BF6: =8.1*((BE6/MPM!$AE7)^(1/6)) -> 11.281387 | BG6: =100*ABS(BF6-BC6)/BF6 -> 3.4076822e-09 | BH6: =(MPM!$Q7^2)/(9.81*MPM!$F7*(BF6^2)) -> 0.41823414 | BI6: =8.1*((BH6/MPM!$AE7)^(1/6)) -> 11.281387 | BJ6: =100*ABS(BI6-BF6)/BI6 -> 1.1358783e-09 | BK6: =(MPM!$Q7^2)/(9.81*MPM!$F7*(BI6^2)) -> 0.41823414 | BL6: =8.1*((BK6/MPM!$AE7)^(1/6)) -> 11.281387 | BM6: =100*ABS(BL6-BI6)/BL6 -> 3.7862611e-10 | BN6: =100*ABS(BK6-BH6)/BK6 -> 2.2717498e-09
A7: =MPM!B8 -> 3 | B7: =1/(MPM!AC8^0.5) -> 11.310433 | C7: =(MPM!$Q8^2)/(9.81*MPM!$F8*(Sheet1!B7^2)) -> 0.36996522 | D7: =8.1*((C7/MPM!$AE8)^(1/6)) -> 11.05315 | E7: =100*ABS(D7-B7)/D7 -> 2.3276847 | F7: =(MPM!$Q8^2)/(9.81*MPM!$F8*(D7^2)) -> 0.38738892 | G7: =8.1*((F7/MPM!$AE8)^(1/6)) -> 11.138254 | H7: =100*ABS(G7-D7)/G7 -> 0.76406848 | I7: =(MPM!$Q8^2)/(9.81*MPM!$F8*(G7^2)) -> 0.3814917 | J7: =8.1*((I7/MPM!$AE8)^(1/6)) -> 11.109813 | K7: =100*ABS(J7-G7)/J7 -> 0.25599459 | L7: =(MPM!$Q8^2)/(9.81*MPM!$F8*(J7^2)) -> 0.3834474 | M7: =8.1*((L7/MPM!$AE8)^(1/6)) -> 11.119285 | N7: =100*ABS(M7-J7)/M7 -> 0.085186189 | O7: =(MPM!$Q8^2)/(9.81*MPM!$F8*(M7^2)) -> 0.38279439 | P7: =8.1*((O7/MPM!$AE8)^(1/6)) -> 11.116127 | Q7: =100*ABS(P7-M7)/P7 -> 0.028411533 | R7: =(MPM!$Q8^2)/(9.81*MPM!$F8*(P7^2)) -> 0.38301193 | S7: =8.1*((R7/MPM!$AE8)^(1/6)) -> 11.11718 | T7: =100*ABS(S7-P7)/S7 -> 0.0094687176 | U7: =(MPM!$Q8^2)/(9.81*MPM!$F8*(S7^2)) -> 0.3829394 | V7: =8.1*((U7/MPM!$AE8)^(1/6)) -> 11.116829 | W7: =100*ABS(V7-S7)/V7 -> 0.0031564385 | X7: =(MPM!$Q8^2)/(9.81*MPM!$F8*(V7^2)) -> 0.38296358 | Y7: =8.1*((X7/MPM!$AE8)^(1/6)) -> 11.116946 | Z7: =100*ABS(Y7-V7)/Y7 -> 0.001052124 | AA7: =(MPM!$Q8^2)/(9.81*MPM!$F8*(Y7^2)) -> 0.38295552 | AB7: =8.1*((AA7/MPM!$AE8)^(1/6)) -> 11.116907 | AC7: =100*ABS(AB7-Y7)/AB7 -> 0.00035071046 | AD7: =(MPM!$Q8^2)/(9.81*MPM!$F8*(AB7^2)) -> 0.38295821 | AE7: =8.1*((AD7/MPM!$AE8)^(1/6)) -> 11.11692 | AF7: =100*ABS(AE7-AB7)/AE7 -> 0.00011690321 | AG7: =(MPM!$Q8^2)/(9.81*MPM!$F8*(AE7^2)) -> 0.38295731 | AH7: =8.1*((AG7/MPM!$AE8)^(1/6)) -> 11.116916 | AI7: =100*ABS(AH7-AE7)/AH7 -> 3.8967769e-05 | AJ7: =(MPM!$Q8^2)/(9.81*MPM!$F8*(AH7^2)) -> 0.38295761 | AK7: =8.1*((AJ7/MPM!$AE8)^(1/6)) -> 11.116917 | AL7: =100*ABS(AK7-AH7)/AK7 -> 1.2989253e-05 | AM7: =(MPM!$Q8^2)/(9.81*MPM!$F8*(AK7^2)) -> 0.38295751 | AN7: =8.1*((AM7/MPM!$AE8)^(1/6)) -> 11.116917 | AO7: =100*ABS(AN7-AK7)/AN7 -> 4.3297513e-06 | AP7: =(MPM!$Q8^2)/(9.81*MPM!$F8*(AN7^2)) -> 0.38295754 | AQ7: =8.1*((AP7/MPM!$AE8)^(1/6)) -> 11.116917 | AR7: =100*ABS(AQ7-AN7)/AQ7 -> 1.4432504e-06 | AS7: =(MPM!$Q8^2)/(9.81*MPM!$F8*(AQ7^2)) -> 0.38295753 | AT7: =8.1*((AS7/MPM!$AE8)^(1/6)) -> 11.116917 | AU7: =100*ABS(AT7-AQ7)/AT7 -> 4.8108348e-07 | AV7: =(MPM!$Q8^2)/(9.81*MPM!$F8*(AT7^2)) -> 0.38295754 | AW7: =8.1*((AV7/MPM!$AE8)^(1/6)) -> 11.116917 | AX7: =100*ABS(AW7-AT7)/AW7 -> 1.6036115e-07 | AY7: =(MPM!$Q8^2)/(9.81*MPM!$F8*(AW7^2)) -> 0.38295753 | AZ7: =8.1*((AY7/MPM!$AE8)^(1/6)) -> 11.116917 | BA7: =100*ABS(AZ7-AW7)/AZ7 -> 5.3453705e-08 | BB7: =(MPM!$Q8^2)/(9.81*MPM!$F8*(AZ7^2)) -> 0.38295754 | BC7: =8.1*((BB7/MPM!$AE8)^(1/6)) -> 11.116917 | BD7: =100*ABS(BC7-AZ7)/BC7 -> 1.7817902e-08 | BE7: =(MPM!$Q8^2)/(9.81*MPM!$F8*(BC7^2)) -> 0.38295753 | BF7: =8.1*((BE7/MPM!$AE8)^(1/6)) -> 11.116917 | BG7: =100*ABS(BF7-BC7)/BF7 -> 5.9393112e-09 | BH7: =(MPM!$Q8^2)/(9.81*MPM!$F8*(BF7^2)) -> 0.38295754 | BI7: =8.1*((BH7/MPM!$AE8)^(1/6)) -> 11.116917 | BJ7: =100*ABS(BI7-BF7)/BI7 -> 1.9797811e-09 | BK7: =(MPM!$Q8^2)/(9.81*MPM!$F8*(BI7^2)) -> 0.38295754 | BL7: =8.1*((BK7/MPM!$AE8)^(1/6)) -> 11.116917 | BM7: =100*ABS(BL7-BI7)/BL7 -> 6.5992702e-10 | BN7: =100*ABS(BK7-BH7)/BK7 -> 3.9595581e-09
A8: =MPM!B9 -> 4 | B8: =1/(MPM!AC9^0.5) -> 11.17135 | C8: =(MPM!$Q9^2)/(9.81*MPM!$F9*(Sheet1!B8^2)) -> 0.37220574 | D8: =8.1*((C8/MPM!$AE9)^(1/6)) -> 11.064278 | E8: =100*ABS(D8-B8)/D8 -> 0.96772536 | F8: =(MPM!$Q9^2)/(9.81*MPM!$F9*(D8^2)) -> 0.37944445 | G8: =8.1*((F8/MPM!$AE9)^(1/6)) -> 11.099854 | H8: =100*ABS(G8-D8)/G8 -> 0.32050956 | I8: =(MPM!$Q9^2)/(9.81*MPM!$F9*(G8^2)) -> 0.37701604 | J8: =8.1*((I8/MPM!$AE9)^(1/6)) -> 11.087983 | K8: =100*ABS(J8-G8)/J8 -> 0.10706537 | L8: =(MPM!$Q9^2)/(9.81*MPM!$F9*(J8^2)) -> 0.37782378 | M8: =8.1*((L8/MPM!$AE9)^(1/6)) -> 11.091939 | N8: =100*ABS(M8-J8)/M8 -> 0.035663005 | O8: =(MPM!$Q9^2)/(9.81*MPM!$F9*(M8^2)) -> 0.37755434 | P8: =8.1*((O8/MPM!$AE9)^(1/6)) -> 11.09062 | Q8: =100*ABS(P8-M8)/P8 -> 0.011890496 | R8: =(MPM!$Q9^2)/(9.81*MPM!$F9*(P8^2)) -> 0.37764413 | S8: =8.1*((R8/MPM!$AE9)^(1/6)) -> 11.09106 | T8: =100*ABS(S8-P8)/S8 -> 0.0039631844 | U8: =(MPM!$Q9^2)/(9.81*MPM!$F9*(S8^2)) -> 0.3776142 | V8: =8.1*((U8/MPM!$AE9)^(1/6)) -> 11.090913 | W8: =100*ABS(V8-S8)/V8 -> 0.0013210964 | X8: =(MPM!$Q9^2)/(9.81*MPM!$F9*(V8^2)) -> 0.37762418 | Y8: =8.1*((X8/MPM!$AE9)^(1/6)) -> 11.090962 | Z8: =100*ABS(Y8-V8)/Y8 -> 0.00044036158 | AA8: =(MPM!$Q9^2)/(9.81*MPM!$F9*(Y8^2)) -> 0.37762085 | AB8: =8.1*((AA8/MPM!$AE9)^(1/6)) -> 11.090946 | AC8: =100*ABS(AB8-Y8)/AB8 -> 0.00014678762 | AD8: =(MPM!$Q9^2)/(9.81*MPM!$F9*(AB8^2)) -> 0.37762196 | AE8: =8.1*((AD8/MPM!$AE9)^(1/6)) -> 11.090951 | AF8: =100*ABS(AE8-AB8)/AE8 -> 4.892916e-05 | AG8: =(MPM!$Q9^2)/(9.81*MPM!$F9*(AE8^2)) -> 0.37762159 | AH8: =8.1*((AG8/MPM!$AE9)^(1/6)) -> 11.090949 | AI8: =100*ABS(AH8-AE8)/AH8 -> 1.6309725e-05 | AJ8: =(MPM!$Q9^2)/(9.81*MPM!$F9*(AH8^2)) -> 0.37762171 | AK8: =8.1*((AJ8/MPM!$AE9)^(1/6)) -> 11.09095 | AL8: =100*ABS(AK8-AH8)/AK8 -> 5.4365745e-06 | AM8: =(MPM!$Q9^2)/(9.81*MPM!$F9*(AK8^2)) -> 0.37762167 | AN8: =8.1*((AM8/MPM!$AE9)^(1/6)) -> 11.09095 | AO8: =100*ABS(AN8-AK8)/AN8 -> 1.8121916e-06 | AP8: =(MPM!$Q9^2)/(9.81*MPM!$F9*(AN8^2)) -> 0.37762169 | AQ8: =8.1*((AP8/MPM!$AE9)^(1/6)) -> 11.09095 | AR8: =100*ABS(AQ8-AN8)/AQ8 -> 6.0406384e-07 | AS8: =(MPM!$Q9^2)/(9.81*MPM!$F9*(AQ8^2)) -> 0.37762168 | AT8: =8.1*((AS8/MPM!$AE9)^(1/6)) -> 11.09095 | AU8: =100*ABS(AT8-AQ8)/AT8 -> 2.0135462e-07 | AV8: =(MPM!$Q9^2)/(9.81*MPM!$F9*(AT8^2)) -> 0.37762168 | AW8: =8.1*((AV8/MPM!$AE9)^(1/6)) -> 11.09095 | AX8: =100*ABS(AW8-AT8)/AW8 -> 6.7118212e-08 | AY8: =(MPM!$Q9^2)/(9.81*MPM!$F9*(AW8^2)) -> 0.37762168 | AZ8: =8.1*((AY8/MPM!$AE9)^(1/6)) -> 11.09095 | BA8: =100*ABS(AZ8-AW8)/AZ8 -> 2.2372732e-08 | BB8: =(MPM!$Q9^2)/(9.81*MPM!$F9*(AZ8^2)) -> 0.37762168 | BC8: =8.1*((BB8/MPM!$AE9)^(1/6)) -> 11.09095 | BD8: =100*ABS(BC8-AZ8)/BC8 -> 7.4575774e-09 | BE8: =(MPM!$Q9^2)/(9.81*MPM!$F9*(BC8^2)) -> 0.37762168 | BF8: =8.1*((BE8/MPM!$AE9)^(1/6)) -> 11.09095 | BG8: =100*ABS(BF8-BC8)/BF8 -> 2.4858698e-09 | BH8: =(MPM!$Q9^2)/(9.81*MPM!$F9*(BF8^2)) -> 0.37762168 | BI8: =8.1*((BH8/MPM!$AE9)^(1/6)) -> 11.09095 | BJ8: =100*ABS(BI8-BF8)/BI8 -> 8.2863394e-10 | BK8: =(MPM!$Q9^2)/(9.81*MPM!$F9*(BI8^2)) -> 0.37762168 | BL8: =8.1*((BK8/MPM!$AE9)^(1/6)) -> 11.09095 | BM8: =100*ABS(BL8-BI8)/BL8 -> 2.7621665e-10 | BN8: =100*ABS(BK8-BH8)/BK8 -> 1.6572714e-09
A9: =MPM!B10 -> 5 | B9: =1/(MPM!AC10^0.5) -> 11.203314 | C9: =(MPM!$Q10^2)/(9.81*MPM!$F10*(Sheet1!B9^2)) -> 0.37208968 | D9: =8.1*((C9/MPM!$AE10)^(1/6)) -> 11.063703 | E9: =100*ABS(D9-B9)/D9 -> 1.2618834 | F9: =(MPM!$Q10^2)/(9.81*MPM!$F10*(D9^2)) -> 0.38153961 | G9: =8.1*((F9/MPM!$AE10)^(1/6)) -> 11.110046 | H9: =100*ABS(G9-D9)/G9 -> 0.41712361 | I9: =(MPM!$Q10^2)/(9.81*MPM!$F10*(G9^2)) -> 0.37836326 | J9: =8.1*((I9/MPM!$AE10)^(1/6)) -> 11.094577 | K9: =100*ABS(J9-G9)/J9 -> 0.13942911 | L9: =(MPM!$Q10^2)/(9.81*MPM!$F10*(J9^2)) -> 0.3794191 | M9: =8.1*((L9/MPM!$AE10)^(1/6)) -> 11.099731 | N9: =100*ABS(M9-J9)/M9 -> 0.046433217 | O9: =(MPM!$Q10^2)/(9.81*MPM!$F10*(M9^2)) -> 0.37906683 | P9: =8.1*((O9/MPM!$AE10)^(1/6)) -> 11.098013 | Q9: =100*ABS(P9-M9)/P9 -> 0.015482532 | R9: =(MPM!$Q10^2)/(9.81*MPM!$F10*(P9^2)) -> 0.37918421 | S9: =8.1*((R9/MPM!$AE10)^(1/6)) -> 11.098585 | T9: =100*ABS(S9-P9)/S9 -> 0.0051603113 | U9: =(MPM!$Q10^2)/(9.81*MPM!$F10*(S9^2)) -> 0.37914508 | V9: =8.1*((U9/MPM!$AE10)^(1/6)) -> 11.098394 | W9: =100*ABS(V9-S9)/V9 -> 0.0017201629 | X9: =(MPM!$Q10^2)/(9.81*MPM!$F10*(V9^2)) -> 0.37915812 | Y9: =8.1*((X9/MPM!$AE10)^(1/6)) -> 11.098458 | Z9: =100*ABS(Y9-V9)/Y9 -> 0.00057338107 | AA9: =(MPM!$Q10^2)/(9.81*MPM!$F10*(Y9^2)) -> 0.37915378 | AB9: =8.1*((AA9/MPM!$AE10)^(1/6)) -> 11.098437 | AC9: =100*ABS(AB9-Y9)/AB9 -> 0.00019112776 | AD9: =(MPM!$Q10^2)/(9.81*MPM!$F10*(AB9^2)) -> 0.37915523 | AE9: =8.1*((AD9/MPM!$AE10)^(1/6)) -> 11.098444 | AF9: =100*ABS(AE9-AB9)/AE9 -> 6.370917e-05 | AG9: =(MPM!$Q10^2)/(9.81*MPM!$F10*(AE9^2)) -> 0.37915474 | AH9: =8.1*((AG9/MPM!$AE10)^(1/6)) -> 11.098442 | AI9: =100*ABS(AH9-AE9)/AH9 -> 2.1236399e-05 | AJ9: =(MPM!$Q10^2)/(9.81*MPM!$F10*(AH9^2)) -> 0.3791549 | AK9: =8.1*((AJ9/MPM!$AE10)^(1/6)) -> 11.098442 | AL9: =100*ABS(AK9-AH9)/AK9 -> 7.0787987e-06 | AM9: =(MPM!$Q10^2)/(9.81*MPM!$F10*(AK9^2)) -> 0.37915485 | AN9: =8.1*((AM9/MPM!$AE10)^(1/6)) -> 11.098442 | AO9: =100*ABS(AN9-AK9)/AN9 -> 2.3595997e-06 | AP9: =(MPM!$Q10^2)/(9.81*MPM!$F10*(AN9^2)) -> 0.37915487 | AQ9: =8.1*((AP9/MPM!$AE10)^(1/6)) -> 11.098442 | AR9: =100*ABS(AQ9-AN9)/AQ9 -> 7.8653318e-07 | AS9: =(MPM!$Q10^2)/(9.81*MPM!$F10*(AQ9^2)) -> 0.37915486 | AT9: =8.1*((AS9/MPM!$AE10)^(1/6)) -> 11.098442 | AU9: =100*ABS(AT9-AQ9)/AT9 -> 2.6217771e-07 | AV9: =(MPM!$Q10^2)/(9.81*MPM!$F10*(AT9^2)) -> 0.37915486 | AW9: =8.1*((AV9/MPM!$AE10)^(1/6)) -> 11.098442 | AX9: =100*ABS(AW9-AT9)/AW9 -> 8.7392555e-08 | AY9: =(MPM!$Q10^2)/(9.81*MPM!$F10*(AW9^2)) -> 0.37915486 | AZ9: =8.1*((AY9/MPM!$AE10)^(1/6)) -> 11.098442 | BA9: =100*ABS(AZ9-AW9)/AZ9 -> 2.9130836e-08 | BB9: =(MPM!$Q10^2)/(9.81*MPM!$F10*(AZ9^2)) -> 0.37915486 | BC9: =8.1*((BB9/MPM!$AE10)^(1/6)) -> 11.098442 | BD9: =100*ABS(BC9-AZ9)/BC9 -> 9.7102732e-09 | BE9: =(MPM!$Q10^2)/(9.81*MPM!$F10*(BC9^2)) -> 0.37915486 | BF9: =8.1*((BE9/MPM!$AE10)^(1/6)) -> 11.098442 | BG9: =100*ABS(BF9-BC9)/BF9 -> 3.2367524e-09 | BH9: =(MPM!$Q10^2)/(9.81*MPM!$F10*(BF9^2)) -> 0.37915486 | BI9: =8.1*((BH9/MPM!$AE10)^(1/6)) -> 11.098442 | BJ9: =100*ABS(BI9-BF9)/BI9 -> 1.0789121e-09 | BK9: =(MPM!$Q10^2)/(9.81*MPM!$F10*(BI9^2)) -> 0.37915486 | BL9: =8.1*((BK9/MPM!$AE10)^(1/6)) -> 11.098442 | BM9: =100*ABS(BL9-BI9)/BL9 -> 3.5962671e-10 | BN9: =100*ABS(BK9-BH9)/BK9 -> 2.1578137e-09
A10: =MPM!B11 -> 6 | B10: =1/(MPM!AC11^0.5) -> 11.255029 | C10: =(MPM!$Q11^2)/(9.81*MPM!$F11*(Sheet1!B10^2)) -> 0.37190162 | D10: =8.1*((C10/MPM!$AE11)^(1/6)) -> 11.062771 | E10: =100*ABS(D10-B10)/D10 -> 1.737878 | F10: =(MPM!$Q11^2)/(9.81*MPM!$F11*(D10^2)) -> 0.38494034 | G10: =8.1*((F10/MPM!$AE11)^(1/6)) -> 11.126489 | H10: =100*ABS(G10-D10)/G10 -> 0.57267048 | I10: =(MPM!$Q11^2)/(9.81*MPM!$F11*(G10^2)) -> 0.38054408 | J10: =8.1*((I10/MPM!$AE11)^(1/6)) -> 11.105209 | K10: =100*ABS(J10-G10)/J10 -> 0.1916222 | L10: =(MPM!$Q11^2)/(9.81*MPM!$F11*(J10^2)) -> 0.38200389 | M10: =8.1*((L10/MPM!$AE11)^(1/6)) -> 11.112298 | N10: =100*ABS(M10-J10)/M10 -> 0.063792591 | O10: =(MPM!$Q11^2)/(9.81*MPM!$F11*(M10^2)) -> 0.38151667 | P10: =8.1*((O10/MPM!$AE11)^(1/6)) -> 11.109935 | Q10: =100*ABS(P10-M10)/P10 -> 0.021273245 | R10: =(MPM!$Q11^2)/(9.81*MPM!$F11*(P10^2)) -> 0.38167901 | S10: =8.1*((R10/MPM!$AE11)^(1/6)) -> 11.110722 | T10: =100*ABS(S10-P10)/S10 -> 0.0070900761 | U10: =(MPM!$Q11^2)/(9.81*MPM!$F11*(S10^2)) -> 0.38162489 | V10: =8.1*((U10/MPM!$AE11)^(1/6)) -> 11.11046 | W10: =100*ABS(V10-S10)/V10 -> 0.0023634704 | X10: =(MPM!$Q11^2)/(9.81*MPM!$F11*(V10^2)) -> 0.38164293 | Y10: =8.1*((X10/MPM!$AE11)^(1/6)) -> 11.110547 | Z10: =100*ABS(Y10-V10)/Y10 -> 0.00078781106 | AA10: =(MPM!$Q11^2)/(9.81*MPM!$F11*(Y10^2)) -> 0.38163691 | AB10: =8.1*((AA10/MPM!$AE11)^(1/6)) -> 11.110518 | AC10: =100*ABS(AB10-Y10)/AB10 -> 0.00026260507 | AD10: =(MPM!$Q11^2)/(9.81*MPM!$F11*(AB10^2)) -> 0.38163892 | AE10: =8.1*((AD10/MPM!$AE11)^(1/6)) -> 11.110528 | AF10: =100*ABS(AE10-AB10)/AE10 -> 8.7534869e-05 | AG10: =(MPM!$Q11^2)/(9.81*MPM!$F11*(AE10^2)) -> 0.38163825 | AH10: =8.1*((AG10/MPM!$AE11)^(1/6)) -> 11.110525 | AI10: =100*ABS(AH10-AE10)/AH10 -> 2.9178307e-05 | AJ10: =(MPM!$Q11^2)/(9.81*MPM!$F11*(AH10^2)) -> 0.38163847 | AK10: =8.1*((AJ10/MPM!$AE11)^(1/6)) -> 11.110526 | AL10: =100*ABS(AK10-AH10)/AK10 -> 9.7261003e-06 | AM10: =(MPM!$Q11^2)/(9.81*MPM!$F11*(AK10^2)) -> 0.3816384 | AN10: =8.1*((AM10/MPM!$AE11)^(1/6)) -> 11.110525 | AO10: =100*ABS(AN10-AK10)/AN10 -> 3.2420337e-06 | AP10: =(MPM!$Q11^2)/(9.81*MPM!$F11*(AN10^2)) -> 0.38163842 | AQ10: =8.1*((AP10/MPM!$AE11)^(1/6)) -> 11.110525 | AR10: =100*ABS(AQ10-AN10)/AQ10 -> 1.0806779e-06 | AS10: =(MPM!$Q11^2)/(9.81*MPM!$F11*(AQ10^2)) -> 0.38163841 | AT10: =8.1*((AS10/MPM!$AE11)^(1/6)) -> 11.110525 | AU10: =100*ABS(AT10-AQ10)/AT10 -> 3.6022597e-07 | AV10: =(MPM!$Q11^2)/(9.81*MPM!$F11*(AT10^2)) -> 0.38163842 | AW10: =8.1*((AV10/MPM!$AE11)^(1/6)) -> 11.110525 | AX10: =100*ABS(AW10-AT10)/AW10 -> 1.2007532e-07 | AY10: =(MPM!$Q11^2)/(9.81*MPM!$F11*(AW10^2)) -> 0.38163842 | AZ10: =8.1*((AY10/MPM!$AE11)^(1/6)) -> 11.110525 | BA10: =100*ABS(AZ10-AW10)/AZ10 -> 4.0025103e-08 | BB10: =(MPM!$Q11^2)/(9.81*MPM!$F11*(AZ10^2)) -> 0.38163842 | BC10: =8.1*((BB10/MPM!$AE11)^(1/6)) -> 11.110525 | BD10: =100*ABS(BC10-AZ10)/BC10 -> 1.3341712e-08 | BE10: =(MPM!$Q11^2)/(9.81*MPM!$F11*(BC10^2)) -> 0.38163842 | BF10: =8.1*((BE10/MPM!$AE11)^(1/6)) -> 11.110525 | BG10: =100*ABS(BF10-BC10)/BF10 -> 4.4472532e-09 | BH10: =(MPM!$Q11^2)/(9.81*MPM!$F11*(BF10^2)) -> 0.38163842 | BI10: =8.1*((BH10/MPM!$AE11)^(1/6)) -> 11.110525 | BJ10: =100*ABS(BI10-BF10)/BI10 -> 1.4824124e-09 | BK10: =(MPM!$Q11^2)/(9.81*MPM!$F11*(BI10^2)) -> 0.38163842 | BL10: =8.1*((BK10/MPM!$AE11)^(1/6)) -> 11.110525 | BM10: =100*ABS(BL10-BI10)/BL10 -> 4.9412681e-10 | BN10: =100*ABS(BK10-BH10)/BK10 -> 2.9648349e-09
A11: =MPM!B12 -> 7 | B11: =1/(MPM!AC12^0.5) -> 11.292393 | C11: =(MPM!$Q12^2)/(9.81*MPM!$F12*(Sheet1!B11^2)) -> 0.3708981 | D11: =8.1*((C11/MPM!$AE12)^(1/6)) -> 11.05779 | E11: =100*ABS(D11-B11)/D11 -> 2.1216016 | F11: =(MPM!$Q12^2)/(9.81*MPM!$F12*(D11^2)) -> 0.38680301 | G11: =8.1*((F11/MPM!$AE12)^(1/6)) -> 11.135444 | H11: =100*ABS(G11-D11)/G11 -> 0.69736006 | I11: =(MPM!$Q12^2)/(9.81*MPM!$F12*(G11^2)) -> 0.381427 | J11: =8.1*((I11/MPM!$AE12)^(1/6)) -> 11.109499 | K11: =100*ABS(J11-G11)/J11 -> 0.23353994 | L11: =(MPM!$Q12^2)/(9.81*MPM!$F12*(J11^2)) -> 0.38321065 | M11: =8.1*((L11/MPM!$AE12)^(1/6)) -> 11.118141 | N11: =100*ABS(M11-J11)/M11 -> 0.077725665 | O11: =(MPM!$Q12^2)/(9.81*MPM!$F12*(M11^2)) -> 0.38261518 | P11: =8.1*((O11/MPM!$AE12)^(1/6)) -> 11.11526 | Q11: =100*ABS(P11-M11)/P11 -> 0.025921988 | R11: =(MPM!$Q12^2)/(9.81*MPM!$F12*(P11^2)) -> 0.38281356 | S11: =8.1*((R11/MPM!$AE12)^(1/6)) -> 11.11622 | T11: =100*ABS(S11-P11)/S11 -> 0.0086391698 | U11: =(MPM!$Q12^2)/(9.81*MPM!$F12*(S11^2)) -> 0.38274742 | V11: =8.1*((U11/MPM!$AE12)^(1/6)) -> 11.1159 | W11: =100*ABS(V11-S11)/V11 -> 0.0028798891 | X11: =(MPM!$Q12^2)/(9.81*MPM!$F12*(V11^2)) -> 0.38276947 | Y11: =8.1*((X11/MPM!$AE12)^(1/6)) -> 11.116007 | Z11: =100*ABS(Y11-V11)/Y11 -> 0.00095994462 | AA11: =(MPM!$Q12^2)/(9.81*MPM!$F12*(Y11^2)) -> 0.38276212 | AB11: =8.1*((AA11/MPM!$AE12)^(1/6)) -> 11.115971 | AC11: =100*ABS(AB11-Y11)/AB11 -> 0.00031998359 | AD11: =(MPM!$Q12^2)/(9.81*MPM!$F12*(AB11^2)) -> 0.38276457 | AE11: =8.1*((AD11/MPM!$AE12)^(1/6)) -> 11.115983 | AF11: =100*ABS(AE11-AB11)/AE11 -> 0.00010666097 | AG11: =(MPM!$Q12^2)/(9.81*MPM!$F12*(AE11^2)) -> 0.38276375 | AH11: =8.1*((AG11/MPM!$AE12)^(1/6)) -> 11.115979 | AI11: =100*ABS(AH11-AE11)/AH11 -> 3.5553681e-05 | AJ11: =(MPM!$Q12^2)/(9.81*MPM!$F12*(AH11^2)) -> 0.38276403 | AK11: =8.1*((AJ11/MPM!$AE12)^(1/6)) -> 11.11598 | AL11: =100*ABS(AK11-AH11)/AK11 -> 1.1851224e-05 | AM11: =(MPM!$Q12^2)/(9.81*MPM!$F12*(AK11^2)) -> 0.38276393 | AN11: =8.1*((AM11/MPM!$AE12)^(1/6)) -> 11.11598 | AO11: =100*ABS(AN11-AK11)/AN11 -> 3.9504084e-06 | AP11: =(MPM!$Q12^2)/(9.81*MPM!$F12*(AN11^2)) -> 0.38276397 | AQ11: =8.1*((AP11/MPM!$AE12)^(1/6)) -> 11.11598 | AR11: =100*ABS(AQ11-AN11)/AQ11 -> 1.3168028e-06 | AS11: =(MPM!$Q12^2)/(9.81*MPM!$F12*(AQ11^2)) -> 0.38276396 | AT11: =8.1*((AS11/MPM!$AE12)^(1/6)) -> 11.11598 | AU11: =100*ABS(AT11-AQ11)/AT11 -> 4.3893425e-07 | AV11: =(MPM!$Q12^2)/(9.81*MPM!$F12*(AT11^2)) -> 0.38276396 | AW11: =8.1*((AV11/MPM!$AE12)^(1/6)) -> 11.11598 | AX11: =100*ABS(AW11-AT11)/AW11 -> 1.4631142e-07 | AY11: =(MPM!$Q12^2)/(9.81*MPM!$F12*(AW11^2)) -> 0.38276396 | AZ11: =8.1*((AY11/MPM!$AE12)^(1/6)) -> 11.11598 | BA11: =100*ABS(AZ11-AW11)/AZ11 -> 4.877048e-08 | BB11: =(MPM!$Q12^2)/(9.81*MPM!$F12*(AZ11^2)) -> 0.38276396 | BC11: =8.1*((BB11/MPM!$AE12)^(1/6)) -> 11.11598 | BD11: =100*ABS(BC11-AZ11)/BC11 -> 1.6256827e-08 | BE11: =(MPM!$Q12^2)/(9.81*MPM!$F12*(BC11^2)) -> 0.38276396 | BF11: =8.1*((BE11/MPM!$AE12)^(1/6)) -> 11.11598 | BG11: =100*ABS(BF11-BC11)/BF11 -> 5.4189368e-09 | BH11: =(MPM!$Q12^2)/(9.81*MPM!$F12*(BF11^2)) -> 0.38276396 | BI11: =8.1*((BH11/MPM!$AE12)^(1/6)) -> 11.11598 | BJ11: =100*ABS(BI11-BF11)/BI11 -> 1.806307e-09 | BK11: =(MPM!$Q12^2)/(9.81*MPM!$F12*(BI11^2)) -> 0.38276396 | BL11: =8.1*((BK11/MPM!$AE12)^(1/6)) -> 11.11598 | BM11: =100*ABS(BL11-BI11)/BL11 -> 6.0210232e-10 | BN11: =100*ABS(BK11-BH11)/BK11 -> 3.6126108e-09
A12: =MPM!B13 -> 8 | B12: =1/(MPM!AC13^0.5) -> 10.301842 | C12: =(MPM!$Q13^2)/(9.81*MPM!$F13*(Sheet1!B12^2)) -> 0.3477701 | D12: =8.1*((C12/MPM!$AE13)^(1/6)) -> 10.939764 | E12: =100*ABS(D12-B12)/D12 -> 5.8312252 | F12: =(MPM!$Q13^2)/(9.81*MPM!$F13*(D12^2)) -> 0.30839411 | G12: =8.1*((F12/MPM!$AE13)^(1/6)) -> 10.722851 | H12: =100*ABS(G12-D12)/G12 -> 2.0229068 | I12: =(MPM!$Q13^2)/(9.81*MPM!$F13*(G12^2)) -> 0.32099736 | J12: =8.1*((I12/MPM!$AE13)^(1/6)) -> 10.794673 | K12: =100*ABS(J12-G12)/J12 -> 0.66534932 | L12: =(MPM!$Q13^2)/(9.81*MPM!$F13*(J12^2)) -> 0.31674007 | M12: =8.1*((L12/MPM!$AE13)^(1/6)) -> 10.770679 | N12: =100*ABS(M12-J12)/M12 -> 0.22277198 | O12: =(MPM!$Q13^2)/(9.81*MPM!$F13*(M12^2)) -> 0.31815285 | P12: =8.1*((O12/MPM!$AE13)^(1/6)) -> 10.778671 | Q12: =100*ABS(P12-M12)/P12 -> 0.074147234 | R12: =(MPM!$Q13^2)/(9.81*MPM!$F13*(P12^2)) -> 0.31768123 | S12: =8.1*((R12/MPM!$AE13)^(1/6)) -> 10.776006 | T12: =100*ABS(S12-P12)/S12 -> 0.024727969 | U12: =(MPM!$Q13^2)/(9.81*MPM!$F13*(S12^2)) -> 0.31783836 | V12: =8.1*((U12/MPM!$AE13)^(1/6)) -> 10.776895 | W12: =100*ABS(V12-S12)/V12 -> 0.0082412978 | X12: =(MPM!$Q13^2)/(9.81*MPM!$F13*(V12^2)) -> 0.31778597 | Y12: =8.1*((X12/MPM!$AE13)^(1/6)) -> 10.776598 | Z12: =100*ABS(Y12-V12)/Y12 -> 0.0027472502 | AA12: =(MPM!$Q13^2)/(9.81*MPM!$F13*(Y12^2)) -> 0.31780343 | AB12: =8.1*((AA12/MPM!$AE13)^(1/6)) -> 10.776697 | AC12: =100*ABS(AB12-Y12)/AB12 -> 0.0009157333 | AD12: =(MPM!$Q13^2)/(9.81*MPM!$F13*(AB12^2)) -> 0.31779761 | AE12: =8.1*((AD12/MPM!$AE13)^(1/6)) -> 10.776664 | AF12: =100*ABS(AE12-AB12)/AE12 -> 0.0003052463 | AG12: =(MPM!$Q13^2)/(9.81*MPM!$F13*(AE12^2)) -> 0.31779955 | AH12: =8.1*((AG12/MPM!$AE13)^(1/6)) -> 10.776675 | AI12: =100*ABS(AH12-AE12)/AH12 -> 0.00010174856 | AJ12: =(MPM!$Q13^2)/(9.81*MPM!$F13*(AH12^2)) -> 0.31779891 | AK12: =8.1*((AJ12/MPM!$AE13)^(1/6)) -> 10.776672 | AL12: =100*ABS(AK12-AH12)/AK12 -> 3.3916209e-05 | AM12: =(MPM!$Q13^2)/(9.81*MPM!$F13*(AK12^2)) -> 0.31779912 | AN12: =8.1*((AM12/MPM!$AE13)^(1/6)) -> 10.776673 | AO12: =100*ABS(AN12-AK12)/AN12 -> 1.1305401e-05 | AP12: =(MPM!$Q13^2)/(9.81*MPM!$F13*(AN12^2)) -> 0.31779905 | AQ12: =8.1*((AP12/MPM!$AE13)^(1/6)) -> 10.776672 | AR12: =100*ABS(AQ12-AN12)/AQ12 -> 3.7684671e-06 | AS12: =(MPM!$Q13^2)/(9.81*MPM!$F13*(AQ12^2)) -> 0.31779907 | AT12: =8.1*((AS12/MPM!$AE13)^(1/6)) -> 10.776673 | AU12: =100*ABS(AT12-AQ12)/AT12 -> 1.2561557e-06 | AV12: =(MPM!$Q13^2)/(9.81*MPM!$F13*(AT12^2)) -> 0.31779907 | AW12: =8.1*((AV12/MPM!$AE13)^(1/6)) -> 10.776672 | AX12: =100*ABS(AW12-AT12)/AW12 -> 4.1871858e-07 | AY12: =(MPM!$Q13^2)/(9.81*MPM!$F13*(AW12^2)) -> 0.31779907 | AZ12: =8.1*((AY12/MPM!$AE13)^(1/6)) -> 10.776673 | BA12: =100*ABS(AZ12-AW12)/AZ12 -> 1.3957286e-07 | BB12: =(MPM!$Q13^2)/(9.81*MPM!$F13*(AZ12^2)) -> 0.31779907 | BC12: =8.1*((BB12/MPM!$AE13)^(1/6)) -> 10.776672 | BD12: =100*ABS(BC12-AZ12)/BC12 -> 4.6524293e-08 | BE12: =(MPM!$Q13^2)/(9.81*MPM!$F13*(BC12^2)) -> 0.31779907 | BF12: =8.1*((BE12/MPM!$AE13)^(1/6)) -> 10.776673 | BG12: =100*ABS(BF12-BC12)/BF12 -> 1.5508114e-08 | BH12: =(MPM!$Q13^2)/(9.81*MPM!$F13*(BF12^2)) -> 0.31779907 | BI12: =8.1*((BH12/MPM!$AE13)^(1/6)) -> 10.776673 | BJ12: =100*ABS(BI12-BF12)/BI12 -> 5.1693769e-09 | BK12: =(MPM!$Q13^2)/(9.81*MPM!$F13*(BI12^2)) -> 0.31779907 | BL12: =8.1*((BK12/MPM!$AE13)^(1/6)) -> 10.776673 | BM12: =100*ABS(BL12-BI12)/BL12 -> 1.7231366e-09 | BN12: =100*ABS(BK12-BH12)/BK12 -> 1.0338746e-08
